Watching for file changes with StatReloader
"GET /number/ HTTP/1.1" 200 2
"GET /heads/ HTTP/1.1" 200 5
"GET /heads/ HTTP/1.1" 200 5
"GET /heads/ HTTP/1.1" 200 5
"GET /heads/ HTTP/1.1" 200 5
"GET /heads/ HTTP/1.1" 200 5
"GET /heads/ HTTP/1.1" 200 5
"GET /heads/ HTTP/1.1" 200 5
"GET /heads/ HTTP/1.1" 200 5
"GET /heads/ HTTP/1.1" 200 5
D:\Python\Django\my_app_2\views.py changed, reloading.
Watching for file changes with StatReloader
"GET /heads/ HTTP/1.1" 200 5
"GET /heads/ HTTP/1.1" 200 5
"GET /heads/ HTTP/1.1" 200 5
"GET /heads/ HTTP/1.1" 200 5
"GET /heads/ HTTP/1.1" 200 5
"GET /heads/ HTTP/1.1" 200 5
"GET /heads/ HTTP/1.1" 200 5
"GET /heads/ HTTP/1.1" 200 5
D:\Python\Django\seminars_proj\settings.py changed, reloading.
Watching for file changes with StatReloader
D:\Python\Django\seminars_proj\settings.py changed, reloading.
Watching for file changes with StatReloader
Watching for file changes with StatReloader
"GET /heads/ HTTP/1.1" 200 5
"GET /heads/ HTTP/1.1" 200 5
"GET /heads/ HTTP/1.1" 200 5
"GET /heads/ HTTP/1.1" 200 5
"GET /heads/ HTTP/1.1" 200 5
"GET /heads/ HTTP/1.1" 200 5
"GET /heads/ HTTP/1.1" 200 5
D:\Python\Django\seminars_proj\settings.py changed, reloading.
Watching for file changes with StatReloader
D:\Python\Django\seminars_proj\settings.py changed, reloading.
INFO 2023-09-10 23:41:45,022 autoreload 10648 14440 Watching for file changes with StatReloader
INFO 2023-09-10 23:41:50,881 basehttp 10648 19624 "GET /heads/ HTTP/1.1" 200 5
INFO 2023-09-10 23:41:51,560 basehttp 10648 19624 "GET /heads/ HTTP/1.1" 200 5
INFO 2023-09-10 23:41:52,025 basehttp 10648 19624 "GET /heads/ HTTP/1.1" 200 5
INFO 2023-09-10 23:41:52,408 basehttp 10648 19624 "GET /heads/ HTTP/1.1" 200 5
INFO 2023-09-10 23:41:52,755 basehttp 10648 19624 "GET /heads/ HTTP/1.1" 200 5
INFO 2023-09-10 23:41:53,151 basehttp 10648 19624 "GET /heads/ HTTP/1.1" 200 5
INFO 2023-09-10 23:41:53,596 basehttp 10648 19624 "GET /heads/ HTTP/1.1" 200 5
INFO 2023-09-10 23:45:14,421 autoreload 10648 14440 D:\Python\Django\my_app_2\views.py changed, reloading.
INFO 2023-09-10 23:45:18,484 autoreload 4448 23668 Watching for file changes with StatReloader
INFO 2023-09-10 23:46:28,980 autoreload 4448 23668 D:\Python\Django\my_app_2\views.py changed, reloading.
INFO 2023-09-10 23:46:31,291 autoreload 16524 7504 Watching for file changes with StatReloader
INFO 2023-09-11 00:16:51,957 autoreload 23128 24556 Watching for file changes with StatReloader
INFO 2023-09-11 00:17:05,723 basehttp 23128 7504 "GET /heads/ HTTP/1.1" 200 5
WARNING 2023-09-11 00:17:13,639 log 23128 7504 Not Found: /main_page
WARNING 2023-09-11 00:17:13,639 basehttp 23128 7504 "GET /main_page HTTP/1.1" 404 3124
INFO 2023-09-11 00:17:37,378 basehttp 23128 7504 "GET /main HTTP/1.1" 301 0
INFO 2023-09-11 00:17:37,388 basehttp 23128 20764 "GET /main/ HTTP/1.1" 200 605
INFO 2023-09-11 00:17:53,705 basehttp 23128 20764 "GET /about_me HTTP/1.1" 301 0
INFO 2023-09-11 00:17:53,715 basehttp 23128 9448 "GET /about_me/ HTTP/1.1" 200 223
INFO 2023-09-11 00:18:52,547 autoreload 23128 24556 D:\Python\Django\my_HW_01\views.py changed, reloading.
INFO 2023-09-11 00:18:53,941 autoreload 8092 23636 Watching for file changes with StatReloader
INFO 2023-09-11 00:22:21,689 autoreload 8092 23636 D:\Python\Django\my_HW_01\views.py changed, reloading.
INFO 2023-09-11 00:22:26,681 autoreload 10204 23564 Watching for file changes with StatReloader
INFO 2023-09-11 00:22:34,806 basehttp 10204 22740 "GET /about_me/ HTTP/1.1" 200 316
WARNING 2023-09-11 00:22:51,972 log 10204 22740 Not Found: /naim
WARNING 2023-09-11 00:22:51,973 basehttp 10204 22740 "GET /naim HTTP/1.1" 404 3109
INFO 2023-09-11 00:22:57,073 basehttp 10204 22740 "GET /main/ HTTP/1.1" 200 341
INFO 2023-09-11 00:24:21,539 autoreload 10204 23564 D:\Python\Django\my_HW_01\views.py changed, reloading.
INFO 2023-09-11 00:24:23,271 autoreload 1544 7556 Watching for file changes with StatReloader
INFO 2023-09-11 00:24:29,795 basehttp 1544 23444 "GET /main/ HTTP/1.1" 200 466
INFO 2023-09-11 00:24:44,302 basehttp 1544 23444 "GET /about_me/ HTTP/1.1" 200 316
INFO 2023-09-11 01:09:30,442 autoreload 13688 4260 Watching for file changes with StatReloader
INFO 2023-09-11 01:09:40,474 basehttp 13688 21884 "GET /about_me/ HTTP/1.1" 200 316
INFO 2023-09-11 01:09:41,872 basehttp 13688 21884 "GET /about_me/ HTTP/1.1" 200 316
INFO 2023-09-11 01:09:46,044 basehttp 13688 21884 "GET /main/ HTTP/1.1" 200 466
INFO 2023-09-11 01:13:56,357 autoreload 15596 20068 Watching for file changes with StatReloader
INFO 2023-09-11 01:14:21,674 autoreload 8900 23868 Watching for file changes with StatReloader
INFO 2023-09-11 01:14:30,380 basehttp 8900 11568 "GET /main/ HTTP/1.1" 200 466
INFO 2023-09-11 01:41:12,887 autoreload 24344 13128 Watching for file changes with StatReloader
INFO 2023-09-11 01:41:23,792 basehttp 24344 25736 "GET /main/ HTTP/1.1" 200 466
INFO 2023-09-11 01:41:25,438 basehttp 24344 25736 "GET /main/ HTTP/1.1" 200 466
INFO 2023-09-11 01:41:32,421 basehttp 24344 26292 "GET /about_me/ HTTP/1.1" 200 316
INFO 2023-09-11 01:44:56,679 autoreload 26452 23108 Watching for file changes with StatReloader
INFO 2023-09-11 01:45:15,517 basehttp 26452 17196 "GET /about_me/ HTTP/1.1" 200 316
INFO 2023-09-11 01:45:21,139 basehttp 26452 14844 "GET /main/ HTTP/1.1" 200 466
INFO 2023-09-11 08:43:34,505 autoreload 4788 21200 Watching for file changes with StatReloader
INFO 2023-09-11 08:43:39,011 basehttp 4788 11984 "GET /main/ HTTP/1.1" 200 466
INFO 2023-09-11 08:43:48,767 basehttp 4788 11984 "GET /about_me/ HTTP/1.1" 200 316
INFO 2023-09-12 11:18:45,867 autoreload 18204 2540 Watching for file changes with StatReloader
INFO 2023-09-14 00:28:26,704 autoreload 15140 12036 Watching for file changes with StatReloader
INFO 2023-09-18 11:53:52,272 autoreload 16096 4220 Watching for file changes with StatReloader
INFO 2023-09-18 12:03:52,150 autoreload 16096 4220 D:\Django_HW\seminars_proj\urls.py changed, reloading.
INFO 2023-09-18 12:03:53,214 autoreload 22768 24260 Watching for file changes with StatReloader
INFO 2023-09-18 12:04:19,916 autoreload 22768 24260 D:\Django_HW\seminars_proj\urls.py changed, reloading.
INFO 2023-09-18 12:04:20,956 autoreload 23412 17556 Watching for file changes with StatReloader
INFO 2023-09-18 12:05:54,896 autoreload 23412 17556 D:\Django_HW\HW_2\urls.py changed, reloading.
INFO 2023-09-18 12:05:55,889 autoreload 21728 24176 Watching for file changes with StatReloader
INFO 2023-09-18 12:06:20,644 autoreload 21728 24176 D:\Django_HW\HW_2\urls.py changed, reloading.
INFO 2023-09-18 12:06:21,605 autoreload 23260 3212 Watching for file changes with StatReloader
INFO 2023-09-18 12:07:08,830 autoreload 23260 3212 D:\Django_HW\HW_2\urls.py changed, reloading.
INFO 2023-09-18 12:07:09,792 autoreload 10604 8128 Watching for file changes with StatReloader
INFO 2023-09-18 13:58:08,861 autoreload 18788 20340 Watching for file changes with StatReloader
INFO 2023-09-18 13:58:16,489 basehttp 18788 23568 "GET / HTTP/1.1" 200 11
WARNING 2023-09-18 13:58:27,238 log 18788 23568 Not Found: /client
WARNING 2023-09-18 13:58:27,239 basehttp 18788 23568 "GET /client HTTP/1.1" 404 3318
ERROR 2023-09-18 13:58:31,940 log 18788 23568 Internal Server Error: /client/1
Traceback (most recent call last):
  File "C:\Users\Asus\AppData\Local\Programs\Python\Python311\Lib\site-packages\django\template\backends\django.py", line 61, in render
    return self.template.render(context)
           ^^^^^^^^^^^^^^^^^^^^^^^^^^^^^
  File "C:\Users\Asus\AppData\Local\Programs\Python\Python311\Lib\site-packages\django\template\base.py", line 175, in render
    return self._render(context)
           ^^^^^^^^^^^^^^^^^^^^^
  File "C:\Users\Asus\AppData\Local\Programs\Python\Python311\Lib\site-packages\django\template\base.py", line 167, in _render
    return self.nodelist.render(context)
           ^^^^^^^^^^^^^^^^^^^^^^^^^^^^^
  File "C:\Users\Asus\AppData\Local\Programs\Python\Python311\Lib\site-packages\django\template\base.py", line 1005, in render
    return SafeString("".join([node.render_annotated(context) for node in self]))
                              ^^^^^^^^^^^^^^^^^^^^^^^^^^^^^^^^^^^^^^^^^^^^^^^^^
  File "C:\Users\Asus\AppData\Local\Programs\Python\Python311\Lib\site-packages\django\template\base.py", line 1005, in <listcomp>
    return SafeString("".join([node.render_annotated(context) for node in self]))
                               ^^^^^^^^^^^^^^^^^^^^^^^^^^^^^^
  File "C:\Users\Asus\AppData\Local\Programs\Python\Python311\Lib\site-packages\django\template\base.py", line 966, in render_annotated
    return self.render(context)
           ^^^^^^^^^^^^^^^^^^^^
  File "C:\Users\Asus\AppData\Local\Programs\Python\Python311\Lib\site-packages\django\template\loader_tags.py", line 132, in render
    compiled_parent = self.get_parent(context)
                      ^^^^^^^^^^^^^^^^^^^^^^^^
  File "C:\Users\Asus\AppData\Local\Programs\Python\Python311\Lib\site-packages\django\template\loader_tags.py", line 129, in get_parent
    return self.find_template(parent, context)
           ^^^^^^^^^^^^^^^^^^^^^^^^^^^^^^^^^^^
  File "C:\Users\Asus\AppData\Local\Programs\Python\Python311\Lib\site-packages\django\template\loader_tags.py", line 107, in find_template
    template, origin = context.template.engine.find_template(
                       ^^^^^^^^^^^^^^^^^^^^^^^^^^^^^^^^^^^^^^
  File "C:\Users\Asus\AppData\Local\Programs\Python\Python311\Lib\site-packages\django\template\engine.py", line 161, in find_template
    raise TemplateDoesNotExist(name, tried=tried)
django.template.exceptions.TemplateDoesNotExist: base.html

The above exception was the direct cause of the following exception:

Traceback (most recent call last):
  File "C:\Users\Asus\AppData\Local\Programs\Python\Python311\Lib\site-packages\django\core\handlers\exception.py", line 55, in inner
    response = get_response(request)
               ^^^^^^^^^^^^^^^^^^^^^
  File "C:\Users\Asus\AppData\Local\Programs\Python\Python311\Lib\site-packages\django\core\handlers\base.py", line 197, in _get_response
    response = wrapped_callback(request, *callback_args, **callback_kwargs)
               ^^^^^^^^^^^^^^^^^^^^^^^^^^^^^^^^^^^^^^^^^^^^^^^^^^^^^^^^^^^^
  File "D:\Django_HW\HW_2\views.py", line 15, in product_of_client
    return render(request, 'HW_2/products_of_client.html', {'client': client,
           ^^^^^^^^^^^^^^^^^^^^^^^^^^^^^^^^^^^^^^^^^^^^^^^^^^^^^^^^^^^^^^^^^^
  File "C:\Users\Asus\AppData\Local\Programs\Python\Python311\Lib\site-packages\django\shortcuts.py", line 24, in render
    content = loader.render_to_string(template_name, context, request, using=using)
              ^^^^^^^^^^^^^^^^^^^^^^^^^^^^^^^^^^^^^^^^^^^^^^^^^^^^^^^^^^^^^^^^^^^^^
  File "C:\Users\Asus\AppData\Local\Programs\Python\Python311\Lib\site-packages\django\template\loader.py", line 62, in render_to_string
    return template.render(context, request)
           ^^^^^^^^^^^^^^^^^^^^^^^^^^^^^^^^^
  File "C:\Users\Asus\AppData\Local\Programs\Python\Python311\Lib\site-packages\django\template\backends\django.py", line 63, in render
    reraise(exc, self.backend)
  File "C:\Users\Asus\AppData\Local\Programs\Python\Python311\Lib\site-packages\django\template\backends\django.py", line 84, in reraise
    raise new from exc
django.template.exceptions.TemplateDoesNotExist: base.html
ERROR 2023-09-18 13:58:31,963 basehttp 18788 23568 "GET /client/1 HTTP/1.1" 500 134713
INFO 2023-09-18 14:00:51,859 autoreload 22952 16564 Watching for file changes with StatReloader
ERROR 2023-09-18 14:00:57,472 log 22952 12740 Internal Server Error: /client/1
Traceback (most recent call last):
  File "C:\Users\Asus\AppData\Local\Programs\Python\Python311\Lib\site-packages\django\template\backends\django.py", line 61, in render
    return self.template.render(context)
           ^^^^^^^^^^^^^^^^^^^^^^^^^^^^^
  File "C:\Users\Asus\AppData\Local\Programs\Python\Python311\Lib\site-packages\django\template\base.py", line 175, in render
    return self._render(context)
           ^^^^^^^^^^^^^^^^^^^^^
  File "C:\Users\Asus\AppData\Local\Programs\Python\Python311\Lib\site-packages\django\template\base.py", line 167, in _render
    return self.nodelist.render(context)
           ^^^^^^^^^^^^^^^^^^^^^^^^^^^^^
  File "C:\Users\Asus\AppData\Local\Programs\Python\Python311\Lib\site-packages\django\template\base.py", line 1005, in render
    return SafeString("".join([node.render_annotated(context) for node in self]))
                              ^^^^^^^^^^^^^^^^^^^^^^^^^^^^^^^^^^^^^^^^^^^^^^^^^
  File "C:\Users\Asus\AppData\Local\Programs\Python\Python311\Lib\site-packages\django\template\base.py", line 1005, in <listcomp>
    return SafeString("".join([node.render_annotated(context) for node in self]))
                               ^^^^^^^^^^^^^^^^^^^^^^^^^^^^^^
  File "C:\Users\Asus\AppData\Local\Programs\Python\Python311\Lib\site-packages\django\template\base.py", line 966, in render_annotated
    return self.render(context)
           ^^^^^^^^^^^^^^^^^^^^
  File "C:\Users\Asus\AppData\Local\Programs\Python\Python311\Lib\site-packages\django\template\loader_tags.py", line 132, in render
    compiled_parent = self.get_parent(context)
                      ^^^^^^^^^^^^^^^^^^^^^^^^
  File "C:\Users\Asus\AppData\Local\Programs\Python\Python311\Lib\site-packages\django\template\loader_tags.py", line 129, in get_parent
    return self.find_template(parent, context)
           ^^^^^^^^^^^^^^^^^^^^^^^^^^^^^^^^^^^
  File "C:\Users\Asus\AppData\Local\Programs\Python\Python311\Lib\site-packages\django\template\loader_tags.py", line 107, in find_template
    template, origin = context.template.engine.find_template(
                       ^^^^^^^^^^^^^^^^^^^^^^^^^^^^^^^^^^^^^^
  File "C:\Users\Asus\AppData\Local\Programs\Python\Python311\Lib\site-packages\django\template\engine.py", line 161, in find_template
    raise TemplateDoesNotExist(name, tried=tried)
django.template.exceptions.TemplateDoesNotExist: base.html

The above exception was the direct cause of the following exception:

Traceback (most recent call last):
  File "C:\Users\Asus\AppData\Local\Programs\Python\Python311\Lib\site-packages\django\core\handlers\exception.py", line 55, in inner
    response = get_response(request)
               ^^^^^^^^^^^^^^^^^^^^^
  File "C:\Users\Asus\AppData\Local\Programs\Python\Python311\Lib\site-packages\django\core\handlers\base.py", line 197, in _get_response
    response = wrapped_callback(request, *callback_args, **callback_kwargs)
               ^^^^^^^^^^^^^^^^^^^^^^^^^^^^^^^^^^^^^^^^^^^^^^^^^^^^^^^^^^^^
  File "D:\Django_HW\HW_2\views.py", line 15, in product_of_client
    return render(request, 'HW_2/products_of_client.html', {'client': client,
           ^^^^^^^^^^^^^^^^^^^^^^^^^^^^^^^^^^^^^^^^^^^^^^^^^^^^^^^^^^^^^^^^^^
  File "C:\Users\Asus\AppData\Local\Programs\Python\Python311\Lib\site-packages\django\shortcuts.py", line 24, in render
    content = loader.render_to_string(template_name, context, request, using=using)
              ^^^^^^^^^^^^^^^^^^^^^^^^^^^^^^^^^^^^^^^^^^^^^^^^^^^^^^^^^^^^^^^^^^^^^
  File "C:\Users\Asus\AppData\Local\Programs\Python\Python311\Lib\site-packages\django\template\loader.py", line 62, in render_to_string
    return template.render(context, request)
           ^^^^^^^^^^^^^^^^^^^^^^^^^^^^^^^^^
  File "C:\Users\Asus\AppData\Local\Programs\Python\Python311\Lib\site-packages\django\template\backends\django.py", line 63, in render
    reraise(exc, self.backend)
  File "C:\Users\Asus\AppData\Local\Programs\Python\Python311\Lib\site-packages\django\template\backends\django.py", line 84, in reraise
    raise new from exc
django.template.exceptions.TemplateDoesNotExist: base.html
ERROR 2023-09-18 14:00:57,497 basehttp 22952 12740 "GET /client/1 HTTP/1.1" 500 134850
INFO 2023-09-18 14:03:52,001 autoreload 22952 16564 D:\Django_HW\seminars_proj\urls.py changed, reloading.
INFO 2023-09-18 14:03:53,056 autoreload 24252 11236 Watching for file changes with StatReloader
INFO 2023-09-18 14:06:41,628 autoreload 20572 22980 Watching for file changes with StatReloader
WARNING 2023-09-18 14:06:46,796 log 20572 2828 Not Found: /client/1
WARNING 2023-09-18 14:06:46,797 basehttp 20572 2828 "GET /client/1 HTTP/1.1" 404 3233
WARNING 2023-09-18 14:06:58,802 log 20572 2828 Not Found: /client
WARNING 2023-09-18 14:06:58,804 basehttp 20572 2828 "GET /client HTTP/1.1" 404 3227
INFO 2023-09-18 14:08:08,936 basehttp 20572 2828 "GET /about_me HTTP/1.1" 301 0
INFO 2023-09-18 14:08:08,944 basehttp 20572 16620 "GET /about_me/ HTTP/1.1" 200 316
INFO 2023-09-18 14:09:24,845 autoreload 20572 22980 D:\Django_HW\HW_2\urls.py changed, reloading.
INFO 2023-09-18 14:09:26,070 autoreload 19796 19140 Watching for file changes with StatReloader
INFO 2023-09-18 14:10:11,047 autoreload 19796 19140 D:\Django_HW\HW_2\urls.py changed, reloading.
INFO 2023-09-18 14:10:12,396 autoreload 23580 24236 Watching for file changes with StatReloader
INFO 2023-09-18 14:11:03,711 autoreload 23580 24236 D:\Django_HW\HW_2\urls.py changed, reloading.
INFO 2023-09-18 14:11:04,659 autoreload 16964 2412 Watching for file changes with StatReloader
INFO 2023-09-18 14:11:10,612 basehttp 16964 680 "GET / HTTP/1.1" 200 11
WARNING 2023-09-18 14:11:18,875 log 16964 680 Not Found: /client/1
WARNING 2023-09-18 14:11:18,876 basehttp 16964 680 "GET /client/1 HTTP/1.1" 404 3233
WARNING 2023-09-18 14:11:35,814 log 16964 680 Not Found: /online_shop
WARNING 2023-09-18 14:11:35,816 basehttp 16964 680 "GET /online_shop HTTP/1.1" 404 3242
ERROR 2023-09-18 14:11:46,845 log 16964 680 Internal Server Error: /online_shop/client/1
Traceback (most recent call last):
  File "C:\Users\Asus\AppData\Local\Programs\Python\Python311\Lib\site-packages\django\template\backends\django.py", line 61, in render
    return self.template.render(context)
           ^^^^^^^^^^^^^^^^^^^^^^^^^^^^^
  File "C:\Users\Asus\AppData\Local\Programs\Python\Python311\Lib\site-packages\django\template\base.py", line 175, in render
    return self._render(context)
           ^^^^^^^^^^^^^^^^^^^^^
  File "C:\Users\Asus\AppData\Local\Programs\Python\Python311\Lib\site-packages\django\template\base.py", line 167, in _render
    return self.nodelist.render(context)
           ^^^^^^^^^^^^^^^^^^^^^^^^^^^^^
  File "C:\Users\Asus\AppData\Local\Programs\Python\Python311\Lib\site-packages\django\template\base.py", line 1005, in render
    return SafeString("".join([node.render_annotated(context) for node in self]))
                              ^^^^^^^^^^^^^^^^^^^^^^^^^^^^^^^^^^^^^^^^^^^^^^^^^
  File "C:\Users\Asus\AppData\Local\Programs\Python\Python311\Lib\site-packages\django\template\base.py", line 1005, in <listcomp>
    return SafeString("".join([node.render_annotated(context) for node in self]))
                               ^^^^^^^^^^^^^^^^^^^^^^^^^^^^^^
  File "C:\Users\Asus\AppData\Local\Programs\Python\Python311\Lib\site-packages\django\template\base.py", line 966, in render_annotated
    return self.render(context)
           ^^^^^^^^^^^^^^^^^^^^
  File "C:\Users\Asus\AppData\Local\Programs\Python\Python311\Lib\site-packages\django\template\loader_tags.py", line 132, in render
    compiled_parent = self.get_parent(context)
                      ^^^^^^^^^^^^^^^^^^^^^^^^
  File "C:\Users\Asus\AppData\Local\Programs\Python\Python311\Lib\site-packages\django\template\loader_tags.py", line 129, in get_parent
    return self.find_template(parent, context)
           ^^^^^^^^^^^^^^^^^^^^^^^^^^^^^^^^^^^
  File "C:\Users\Asus\AppData\Local\Programs\Python\Python311\Lib\site-packages\django\template\loader_tags.py", line 107, in find_template
    template, origin = context.template.engine.find_template(
                       ^^^^^^^^^^^^^^^^^^^^^^^^^^^^^^^^^^^^^^
  File "C:\Users\Asus\AppData\Local\Programs\Python\Python311\Lib\site-packages\django\template\engine.py", line 161, in find_template
    raise TemplateDoesNotExist(name, tried=tried)
django.template.exceptions.TemplateDoesNotExist: base.html

The above exception was the direct cause of the following exception:

Traceback (most recent call last):
  File "C:\Users\Asus\AppData\Local\Programs\Python\Python311\Lib\site-packages\django\core\handlers\exception.py", line 55, in inner
    response = get_response(request)
               ^^^^^^^^^^^^^^^^^^^^^
  File "C:\Users\Asus\AppData\Local\Programs\Python\Python311\Lib\site-packages\django\core\handlers\base.py", line 197, in _get_response
    response = wrapped_callback(request, *callback_args, **callback_kwargs)
               ^^^^^^^^^^^^^^^^^^^^^^^^^^^^^^^^^^^^^^^^^^^^^^^^^^^^^^^^^^^^
  File "D:\Django_HW\HW_2\views.py", line 15, in product_of_client
    return render(request, 'HW_2/products_of_client.html', {'client': client,
           ^^^^^^^^^^^^^^^^^^^^^^^^^^^^^^^^^^^^^^^^^^^^^^^^^^^^^^^^^^^^^^^^^^
  File "C:\Users\Asus\AppData\Local\Programs\Python\Python311\Lib\site-packages\django\shortcuts.py", line 24, in render
    content = loader.render_to_string(template_name, context, request, using=using)
              ^^^^^^^^^^^^^^^^^^^^^^^^^^^^^^^^^^^^^^^^^^^^^^^^^^^^^^^^^^^^^^^^^^^^^
  File "C:\Users\Asus\AppData\Local\Programs\Python\Python311\Lib\site-packages\django\template\loader.py", line 62, in render_to_string
    return template.render(context, request)
           ^^^^^^^^^^^^^^^^^^^^^^^^^^^^^^^^^
  File "C:\Users\Asus\AppData\Local\Programs\Python\Python311\Lib\site-packages\django\template\backends\django.py", line 63, in render
    reraise(exc, self.backend)
  File "C:\Users\Asus\AppData\Local\Programs\Python\Python311\Lib\site-packages\django\template\backends\django.py", line 84, in reraise
    raise new from exc
django.template.exceptions.TemplateDoesNotExist: base.html
ERROR 2023-09-18 14:11:46,865 basehttp 16964 680 "GET /online_shop/client/1 HTTP/1.1" 500 134867
WARNING 2023-09-18 14:11:55,683 log 16964 680 Not Found: /online_shop
WARNING 2023-09-18 14:11:55,685 basehttp 16964 680 "GET /online_shop HTTP/1.1" 404 3242
INFO 2023-09-18 14:12:58,317 autoreload 16964 2412 D:\Django_HW\seminars_proj\urls.py changed, reloading.
INFO 2023-09-18 14:12:59,332 autoreload 19092 17296 Watching for file changes with StatReloader
INFO 2023-09-18 14:15:20,318 autoreload 19092 17296 D:\Django_HW\HW_2\views.py changed, reloading.
INFO 2023-09-18 14:15:21,533 autoreload 10152 24116 Watching for file changes with StatReloader
ERROR 2023-09-18 14:15:27,112 log 10152 23204 Internal Server Error: /client/1
Traceback (most recent call last):
  File "C:\Users\Asus\AppData\Local\Programs\Python\Python311\Lib\site-packages\django\core\handlers\exception.py", line 55, in inner
    response = get_response(request)
               ^^^^^^^^^^^^^^^^^^^^^
  File "C:\Users\Asus\AppData\Local\Programs\Python\Python311\Lib\site-packages\django\core\handlers\base.py", line 197, in _get_response
    response = wrapped_callback(request, *callback_args, **callback_kwargs)
               ^^^^^^^^^^^^^^^^^^^^^^^^^^^^^^^^^^^^^^^^^^^^^^^^^^^^^^^^^^^^
TypeError: product_of_client() got an unexpected keyword argument 'customer_id'
ERROR 2023-09-18 14:15:27,117 basehttp 10152 23204 "GET /client/1 HTTP/1.1" 500 64048
INFO 2023-09-18 14:15:55,806 autoreload 10152 24116 D:\Django_HW\HW_2\views.py changed, reloading.
INFO 2023-09-18 14:15:56,965 autoreload 15580 22688 Watching for file changes with StatReloader
ERROR 2023-09-18 14:16:00,036 log 15580 23128 Internal Server Error: /client/1
Traceback (most recent call last):
  File "C:\Users\Asus\AppData\Local\Programs\Python\Python311\Lib\site-packages\django\core\handlers\exception.py", line 55, in inner
    response = get_response(request)
               ^^^^^^^^^^^^^^^^^^^^^
  File "C:\Users\Asus\AppData\Local\Programs\Python\Python311\Lib\site-packages\django\core\handlers\base.py", line 197, in _get_response
    response = wrapped_callback(request, *callback_args, **callback_kwargs)
               ^^^^^^^^^^^^^^^^^^^^^^^^^^^^^^^^^^^^^^^^^^^^^^^^^^^^^^^^^^^^
TypeError: product_of_client() got an unexpected keyword argument 'customer_id'
ERROR 2023-09-18 14:16:00,040 basehttp 15580 23128 "GET /client/1 HTTP/1.1" 500 64185
ERROR 2023-09-18 14:16:05,523 log 15580 23128 Internal Server Error: /client/1
Traceback (most recent call last):
  File "C:\Users\Asus\AppData\Local\Programs\Python\Python311\Lib\site-packages\django\core\handlers\exception.py", line 55, in inner
    response = get_response(request)
               ^^^^^^^^^^^^^^^^^^^^^
  File "C:\Users\Asus\AppData\Local\Programs\Python\Python311\Lib\site-packages\django\core\handlers\base.py", line 197, in _get_response
    response = wrapped_callback(request, *callback_args, **callback_kwargs)
               ^^^^^^^^^^^^^^^^^^^^^^^^^^^^^^^^^^^^^^^^^^^^^^^^^^^^^^^^^^^^
TypeError: product_of_client() got an unexpected keyword argument 'customer_id'
ERROR 2023-09-18 14:16:05,528 basehttp 15580 23128 "GET /client/1 HTTP/1.1" 500 64185
INFO 2023-09-18 14:17:37,217 autoreload 17588 21776 Watching for file changes with StatReloader
ERROR 2023-09-18 14:17:40,370 log 17588 23648 Internal Server Error: /client/1
Traceback (most recent call last):
  File "C:\Users\Asus\AppData\Local\Programs\Python\Python311\Lib\site-packages\django\core\handlers\exception.py", line 55, in inner
    response = get_response(request)
               ^^^^^^^^^^^^^^^^^^^^^
  File "C:\Users\Asus\AppData\Local\Programs\Python\Python311\Lib\site-packages\django\core\handlers\base.py", line 197, in _get_response
    response = wrapped_callback(request, *callback_args, **callback_kwargs)
               ^^^^^^^^^^^^^^^^^^^^^^^^^^^^^^^^^^^^^^^^^^^^^^^^^^^^^^^^^^^^
TypeError: product_of_client() got an unexpected keyword argument 'customer_id'
ERROR 2023-09-18 14:17:40,376 basehttp 17588 23648 "GET /client/1 HTTP/1.1" 500 64185
ERROR 2023-09-18 14:17:41,370 log 17588 23648 Internal Server Error: /client/1
Traceback (most recent call last):
  File "C:\Users\Asus\AppData\Local\Programs\Python\Python311\Lib\site-packages\django\core\handlers\exception.py", line 55, in inner
    response = get_response(request)
               ^^^^^^^^^^^^^^^^^^^^^
  File "C:\Users\Asus\AppData\Local\Programs\Python\Python311\Lib\site-packages\django\core\handlers\base.py", line 197, in _get_response
    response = wrapped_callback(request, *callback_args, **callback_kwargs)
               ^^^^^^^^^^^^^^^^^^^^^^^^^^^^^^^^^^^^^^^^^^^^^^^^^^^^^^^^^^^^
TypeError: product_of_client() got an unexpected keyword argument 'customer_id'
ERROR 2023-09-18 14:17:41,378 basehttp 17588 23648 "GET /client/1 HTTP/1.1" 500 64185
ERROR 2023-09-18 14:17:44,033 log 17588 23648 Internal Server Error: /client/1
Traceback (most recent call last):
  File "C:\Users\Asus\AppData\Local\Programs\Python\Python311\Lib\site-packages\django\core\handlers\exception.py", line 55, in inner
    response = get_response(request)
               ^^^^^^^^^^^^^^^^^^^^^
  File "C:\Users\Asus\AppData\Local\Programs\Python\Python311\Lib\site-packages\django\core\handlers\base.py", line 197, in _get_response
    response = wrapped_callback(request, *callback_args, **callback_kwargs)
               ^^^^^^^^^^^^^^^^^^^^^^^^^^^^^^^^^^^^^^^^^^^^^^^^^^^^^^^^^^^^
TypeError: product_of_client() got an unexpected keyword argument 'customer_id'
ERROR 2023-09-18 14:17:44,037 basehttp 17588 23648 "GET /client/1 HTTP/1.1" 500 64185
INFO 2023-09-18 14:17:55,930 autoreload 22932 22604 Watching for file changes with StatReloader
INFO 2023-09-18 14:18:01,192 basehttp 22932 20548 "GET / HTTP/1.1" 200 11
ERROR 2023-09-18 14:18:10,009 log 22932 20548 Internal Server Error: /client/1
Traceback (most recent call last):
  File "C:\Users\Asus\AppData\Local\Programs\Python\Python311\Lib\site-packages\django\core\handlers\exception.py", line 55, in inner
    response = get_response(request)
               ^^^^^^^^^^^^^^^^^^^^^
  File "C:\Users\Asus\AppData\Local\Programs\Python\Python311\Lib\site-packages\django\core\handlers\base.py", line 197, in _get_response
    response = wrapped_callback(request, *callback_args, **callback_kwargs)
               ^^^^^^^^^^^^^^^^^^^^^^^^^^^^^^^^^^^^^^^^^^^^^^^^^^^^^^^^^^^^
TypeError: product_of_client() got an unexpected keyword argument 'customer_id'
ERROR 2023-09-18 14:18:10,014 basehttp 22932 20548 "GET /client/1 HTTP/1.1" 500 64048
WARNING 2023-09-18 14:18:19,422 log 22932 20548 Not Found: /customer_id/1
WARNING 2023-09-18 14:18:19,423 basehttp 22932 20548 "GET /customer_id/1 HTTP/1.1" 404 3339
INFO 2023-09-18 14:18:44,376 autoreload 22932 22604 D:\Django_HW\HW_2\urls.py changed, reloading.
INFO 2023-09-18 14:18:45,411 autoreload 21796 23400 Watching for file changes with StatReloader
ERROR 2023-09-18 14:18:53,041 log 21796 20204 Internal Server Error: /client/1
Traceback (most recent call last):
  File "C:\Users\Asus\AppData\Local\Programs\Python\Python311\Lib\site-packages\django\core\handlers\exception.py", line 55, in inner
    response = get_response(request)
               ^^^^^^^^^^^^^^^^^^^^^
  File "C:\Users\Asus\AppData\Local\Programs\Python\Python311\Lib\site-packages\django\core\handlers\base.py", line 197, in _get_response
    response = wrapped_callback(request, *callback_args, **callback_kwargs)
               ^^^^^^^^^^^^^^^^^^^^^^^^^^^^^^^^^^^^^^^^^^^^^^^^^^^^^^^^^^^^
  File "D:\Django_HW\HW_2\views.py", line 12, in product_of_client
    orders = Order.objects.filter(client_id=client_id).all()
             ^^^^^^^^^^^^^^^^^^^^^^^^^^^^^^^^^^^^^^^^^
  File "C:\Users\Asus\AppData\Local\Programs\Python\Python311\Lib\site-packages\django\db\models\manager.py", line 87, in manager_method
    return getattr(self.get_queryset(), name)(*args, **kwargs)
           ^^^^^^^^^^^^^^^^^^^^^^^^^^^^^^^^^^^^^^^^^^^^^^^^^^^
  File "C:\Users\Asus\AppData\Local\Programs\Python\Python311\Lib\site-packages\django\db\models\query.py", line 1436, in filter
    return self._filter_or_exclude(False, args, kwargs)
           ^^^^^^^^^^^^^^^^^^^^^^^^^^^^^^^^^^^^^^^^^^^^
  File "C:\Users\Asus\AppData\Local\Programs\Python\Python311\Lib\site-packages\django\db\models\query.py", line 1454, in _filter_or_exclude
    clone._filter_or_exclude_inplace(negate, args, kwargs)
  File "C:\Users\Asus\AppData\Local\Programs\Python\Python311\Lib\site-packages\django\db\models\query.py", line 1461, in _filter_or_exclude_inplace
    self._query.add_q(Q(*args, **kwargs))
  File "C:\Users\Asus\AppData\Local\Programs\Python\Python311\Lib\site-packages\django\db\models\sql\query.py", line 1545, in add_q
    clause, _ = self._add_q(q_object, self.used_aliases)
                ^^^^^^^^^^^^^^^^^^^^^^^^^^^^^^^^^^^^^^^^
  File "C:\Users\Asus\AppData\Local\Programs\Python\Python311\Lib\site-packages\django\db\models\sql\query.py", line 1576, in _add_q
    child_clause, needed_inner = self.build_filter(
                                 ^^^^^^^^^^^^^^^^^^
  File "C:\Users\Asus\AppData\Local\Programs\Python\Python311\Lib\site-packages\django\db\models\sql\query.py", line 1426, in build_filter
    lookups, parts, reffed_expression = self.solve_lookup_type(arg, summarize)
                                        ^^^^^^^^^^^^^^^^^^^^^^^^^^^^^^^^^^^^^^
  File "C:\Users\Asus\AppData\Local\Programs\Python\Python311\Lib\site-packages\django\db\models\sql\query.py", line 1236, in solve_lookup_type
    _, field, _, lookup_parts = self.names_to_path(lookup_splitted, self.get_meta())
                                ^^^^^^^^^^^^^^^^^^^^^^^^^^^^^^^^^^^^^^^^^^^^^^^^^^^^
  File "C:\Users\Asus\AppData\Local\Programs\Python\Python311\Lib\site-packages\django\db\models\sql\query.py", line 1724, in names_to_path
    raise FieldError(
django.core.exceptions.FieldError: Cannot resolve keyword 'client_id' into field. Choices are: customer, customer_id, date_ordered, id, products, total_price
ERROR 2023-09-18 14:18:53,065 basehttp 21796 20204 "GET /client/1 HTTP/1.1" 500 114406
INFO 2023-09-18 14:19:46,849 autoreload 21796 23400 D:\Django_HW\HW_2\urls.py changed, reloading.
INFO 2023-09-18 14:19:47,887 autoreload 23932 23616 Watching for file changes with StatReloader
INFO 2023-09-18 14:20:03,372 autoreload 23932 23616 D:\Django_HW\HW_2\views.py changed, reloading.
INFO 2023-09-18 14:20:04,501 autoreload 22064 15000 Watching for file changes with StatReloader
ERROR 2023-09-18 14:20:08,173 log 22064 12596 Internal Server Error: /client/1
Traceback (most recent call last):
  File "C:\Users\Asus\AppData\Local\Programs\Python\Python311\Lib\site-packages\django\template\backends\django.py", line 61, in render
    return self.template.render(context)
           ^^^^^^^^^^^^^^^^^^^^^^^^^^^^^
  File "C:\Users\Asus\AppData\Local\Programs\Python\Python311\Lib\site-packages\django\template\base.py", line 175, in render
    return self._render(context)
           ^^^^^^^^^^^^^^^^^^^^^
  File "C:\Users\Asus\AppData\Local\Programs\Python\Python311\Lib\site-packages\django\template\base.py", line 167, in _render
    return self.nodelist.render(context)
           ^^^^^^^^^^^^^^^^^^^^^^^^^^^^^
  File "C:\Users\Asus\AppData\Local\Programs\Python\Python311\Lib\site-packages\django\template\base.py", line 1005, in render
    return SafeString("".join([node.render_annotated(context) for node in self]))
                              ^^^^^^^^^^^^^^^^^^^^^^^^^^^^^^^^^^^^^^^^^^^^^^^^^
  File "C:\Users\Asus\AppData\Local\Programs\Python\Python311\Lib\site-packages\django\template\base.py", line 1005, in <listcomp>
    return SafeString("".join([node.render_annotated(context) for node in self]))
                               ^^^^^^^^^^^^^^^^^^^^^^^^^^^^^^
  File "C:\Users\Asus\AppData\Local\Programs\Python\Python311\Lib\site-packages\django\template\base.py", line 966, in render_annotated
    return self.render(context)
           ^^^^^^^^^^^^^^^^^^^^
  File "C:\Users\Asus\AppData\Local\Programs\Python\Python311\Lib\site-packages\django\template\loader_tags.py", line 132, in render
    compiled_parent = self.get_parent(context)
                      ^^^^^^^^^^^^^^^^^^^^^^^^
  File "C:\Users\Asus\AppData\Local\Programs\Python\Python311\Lib\site-packages\django\template\loader_tags.py", line 129, in get_parent
    return self.find_template(parent, context)
           ^^^^^^^^^^^^^^^^^^^^^^^^^^^^^^^^^^^
  File "C:\Users\Asus\AppData\Local\Programs\Python\Python311\Lib\site-packages\django\template\loader_tags.py", line 107, in find_template
    template, origin = context.template.engine.find_template(
                       ^^^^^^^^^^^^^^^^^^^^^^^^^^^^^^^^^^^^^^
  File "C:\Users\Asus\AppData\Local\Programs\Python\Python311\Lib\site-packages\django\template\engine.py", line 161, in find_template
    raise TemplateDoesNotExist(name, tried=tried)
django.template.exceptions.TemplateDoesNotExist: base.html

The above exception was the direct cause of the following exception:

Traceback (most recent call last):
  File "C:\Users\Asus\AppData\Local\Programs\Python\Python311\Lib\site-packages\django\core\handlers\exception.py", line 55, in inner
    response = get_response(request)
               ^^^^^^^^^^^^^^^^^^^^^
  File "C:\Users\Asus\AppData\Local\Programs\Python\Python311\Lib\site-packages\django\core\handlers\base.py", line 197, in _get_response
    response = wrapped_callback(request, *callback_args, **callback_kwargs)
               ^^^^^^^^^^^^^^^^^^^^^^^^^^^^^^^^^^^^^^^^^^^^^^^^^^^^^^^^^^^^
  File "D:\Django_HW\HW_2\views.py", line 15, in product_of_client
    return render(request, 'HW_2/products_of_client.html', {'client': client,
           ^^^^^^^^^^^^^^^^^^^^^^^^^^^^^^^^^^^^^^^^^^^^^^^^^^^^^^^^^^^^^^^^^^
  File "C:\Users\Asus\AppData\Local\Programs\Python\Python311\Lib\site-packages\django\shortcuts.py", line 24, in render
    content = loader.render_to_string(template_name, context, request, using=using)
              ^^^^^^^^^^^^^^^^^^^^^^^^^^^^^^^^^^^^^^^^^^^^^^^^^^^^^^^^^^^^^^^^^^^^^
  File "C:\Users\Asus\AppData\Local\Programs\Python\Python311\Lib\site-packages\django\template\loader.py", line 62, in render_to_string
    return template.render(context, request)
           ^^^^^^^^^^^^^^^^^^^^^^^^^^^^^^^^^
  File "C:\Users\Asus\AppData\Local\Programs\Python\Python311\Lib\site-packages\django\template\backends\django.py", line 63, in render
    reraise(exc, self.backend)
  File "C:\Users\Asus\AppData\Local\Programs\Python\Python311\Lib\site-packages\django\template\backends\django.py", line 84, in reraise
    raise new from exc
django.template.exceptions.TemplateDoesNotExist: base.html
ERROR 2023-09-18 14:20:08,197 basehttp 22064 12596 "GET /client/1 HTTP/1.1" 500 134836
INFO 2023-09-18 14:23:41,967 autoreload 21660 22612 Watching for file changes with StatReloader
ERROR 2023-09-18 14:23:50,716 log 21660 24344 Internal Server Error: /client/1
Traceback (most recent call last):
  File "C:\Users\Asus\AppData\Local\Programs\Python\Python311\Lib\site-packages\django\template\backends\django.py", line 61, in render
    return self.template.render(context)
           ^^^^^^^^^^^^^^^^^^^^^^^^^^^^^
  File "C:\Users\Asus\AppData\Local\Programs\Python\Python311\Lib\site-packages\django\template\base.py", line 175, in render
    return self._render(context)
           ^^^^^^^^^^^^^^^^^^^^^
  File "C:\Users\Asus\AppData\Local\Programs\Python\Python311\Lib\site-packages\django\template\base.py", line 167, in _render
    return self.nodelist.render(context)
           ^^^^^^^^^^^^^^^^^^^^^^^^^^^^^
  File "C:\Users\Asus\AppData\Local\Programs\Python\Python311\Lib\site-packages\django\template\base.py", line 1005, in render
    return SafeString("".join([node.render_annotated(context) for node in self]))
                              ^^^^^^^^^^^^^^^^^^^^^^^^^^^^^^^^^^^^^^^^^^^^^^^^^
  File "C:\Users\Asus\AppData\Local\Programs\Python\Python311\Lib\site-packages\django\template\base.py", line 1005, in <listcomp>
    return SafeString("".join([node.render_annotated(context) for node in self]))
                               ^^^^^^^^^^^^^^^^^^^^^^^^^^^^^^
  File "C:\Users\Asus\AppData\Local\Programs\Python\Python311\Lib\site-packages\django\template\base.py", line 966, in render_annotated
    return self.render(context)
           ^^^^^^^^^^^^^^^^^^^^
  File "C:\Users\Asus\AppData\Local\Programs\Python\Python311\Lib\site-packages\django\template\loader_tags.py", line 132, in render
    compiled_parent = self.get_parent(context)
                      ^^^^^^^^^^^^^^^^^^^^^^^^
  File "C:\Users\Asus\AppData\Local\Programs\Python\Python311\Lib\site-packages\django\template\loader_tags.py", line 129, in get_parent
    return self.find_template(parent, context)
           ^^^^^^^^^^^^^^^^^^^^^^^^^^^^^^^^^^^
  File "C:\Users\Asus\AppData\Local\Programs\Python\Python311\Lib\site-packages\django\template\loader_tags.py", line 107, in find_template
    template, origin = context.template.engine.find_template(
                       ^^^^^^^^^^^^^^^^^^^^^^^^^^^^^^^^^^^^^^
  File "C:\Users\Asus\AppData\Local\Programs\Python\Python311\Lib\site-packages\django\template\engine.py", line 161, in find_template
    raise TemplateDoesNotExist(name, tried=tried)
django.template.exceptions.TemplateDoesNotExist: base.html

The above exception was the direct cause of the following exception:

Traceback (most recent call last):
  File "C:\Users\Asus\AppData\Local\Programs\Python\Python311\Lib\site-packages\django\core\handlers\exception.py", line 55, in inner
    response = get_response(request)
               ^^^^^^^^^^^^^^^^^^^^^
  File "C:\Users\Asus\AppData\Local\Programs\Python\Python311\Lib\site-packages\django\core\handlers\base.py", line 197, in _get_response
    response = wrapped_callback(request, *callback_args, **callback_kwargs)
               ^^^^^^^^^^^^^^^^^^^^^^^^^^^^^^^^^^^^^^^^^^^^^^^^^^^^^^^^^^^^
  File "D:\Django_HW\HW_2\views.py", line 15, in product_of_client
    return render(request, 'HW_2/products_of_client.html', {'client': client,
           ^^^^^^^^^^^^^^^^^^^^^^^^^^^^^^^^^^^^^^^^^^^^^^^^^^^^^^^^^^^^^^^^^^
  File "C:\Users\Asus\AppData\Local\Programs\Python\Python311\Lib\site-packages\django\shortcuts.py", line 24, in render
    content = loader.render_to_string(template_name, context, request, using=using)
              ^^^^^^^^^^^^^^^^^^^^^^^^^^^^^^^^^^^^^^^^^^^^^^^^^^^^^^^^^^^^^^^^^^^^^
  File "C:\Users\Asus\AppData\Local\Programs\Python\Python311\Lib\site-packages\django\template\loader.py", line 62, in render_to_string
    return template.render(context, request)
           ^^^^^^^^^^^^^^^^^^^^^^^^^^^^^^^^^
  File "C:\Users\Asus\AppData\Local\Programs\Python\Python311\Lib\site-packages\django\template\backends\django.py", line 63, in render
    reraise(exc, self.backend)
  File "C:\Users\Asus\AppData\Local\Programs\Python\Python311\Lib\site-packages\django\template\backends\django.py", line 84, in reraise
    raise new from exc
django.template.exceptions.TemplateDoesNotExist: base.html
ERROR 2023-09-18 14:23:50,739 basehttp 21660 24344 "GET /client/1 HTTP/1.1" 500 134836
INFO 2023-09-18 14:26:39,847 autoreload 21476 23260 Watching for file changes with StatReloader
ERROR 2023-09-18 14:26:43,912 log 21476 23476 Internal Server Error: /client/1
Traceback (most recent call last):
  File "C:\Users\Asus\AppData\Local\Programs\Python\Python311\Lib\site-packages\django\template\backends\django.py", line 61, in render
    return self.template.render(context)
           ^^^^^^^^^^^^^^^^^^^^^^^^^^^^^
  File "C:\Users\Asus\AppData\Local\Programs\Python\Python311\Lib\site-packages\django\template\base.py", line 175, in render
    return self._render(context)
           ^^^^^^^^^^^^^^^^^^^^^
  File "C:\Users\Asus\AppData\Local\Programs\Python\Python311\Lib\site-packages\django\template\base.py", line 167, in _render
    return self.nodelist.render(context)
           ^^^^^^^^^^^^^^^^^^^^^^^^^^^^^
  File "C:\Users\Asus\AppData\Local\Programs\Python\Python311\Lib\site-packages\django\template\base.py", line 1005, in render
    return SafeString("".join([node.render_annotated(context) for node in self]))
                              ^^^^^^^^^^^^^^^^^^^^^^^^^^^^^^^^^^^^^^^^^^^^^^^^^
  File "C:\Users\Asus\AppData\Local\Programs\Python\Python311\Lib\site-packages\django\template\base.py", line 1005, in <listcomp>
    return SafeString("".join([node.render_annotated(context) for node in self]))
                               ^^^^^^^^^^^^^^^^^^^^^^^^^^^^^^
  File "C:\Users\Asus\AppData\Local\Programs\Python\Python311\Lib\site-packages\django\template\base.py", line 966, in render_annotated
    return self.render(context)
           ^^^^^^^^^^^^^^^^^^^^
  File "C:\Users\Asus\AppData\Local\Programs\Python\Python311\Lib\site-packages\django\template\loader_tags.py", line 132, in render
    compiled_parent = self.get_parent(context)
                      ^^^^^^^^^^^^^^^^^^^^^^^^
  File "C:\Users\Asus\AppData\Local\Programs\Python\Python311\Lib\site-packages\django\template\loader_tags.py", line 129, in get_parent
    return self.find_template(parent, context)
           ^^^^^^^^^^^^^^^^^^^^^^^^^^^^^^^^^^^
  File "C:\Users\Asus\AppData\Local\Programs\Python\Python311\Lib\site-packages\django\template\loader_tags.py", line 107, in find_template
    template, origin = context.template.engine.find_template(
                       ^^^^^^^^^^^^^^^^^^^^^^^^^^^^^^^^^^^^^^
  File "C:\Users\Asus\AppData\Local\Programs\Python\Python311\Lib\site-packages\django\template\engine.py", line 161, in find_template
    raise TemplateDoesNotExist(name, tried=tried)
django.template.exceptions.TemplateDoesNotExist: base.html

The above exception was the direct cause of the following exception:

Traceback (most recent call last):
  File "C:\Users\Asus\AppData\Local\Programs\Python\Python311\Lib\site-packages\django\core\handlers\exception.py", line 55, in inner
    response = get_response(request)
               ^^^^^^^^^^^^^^^^^^^^^
  File "C:\Users\Asus\AppData\Local\Programs\Python\Python311\Lib\site-packages\django\core\handlers\base.py", line 197, in _get_response
    response = wrapped_callback(request, *callback_args, **callback_kwargs)
               ^^^^^^^^^^^^^^^^^^^^^^^^^^^^^^^^^^^^^^^^^^^^^^^^^^^^^^^^^^^^
  File "D:\Django_HW\HW_2\views.py", line 15, in product_of_client
    return render(request, 'HW_2/products_of_client.html', {'client': client,
           ^^^^^^^^^^^^^^^^^^^^^^^^^^^^^^^^^^^^^^^^^^^^^^^^^^^^^^^^^^^^^^^^^^
  File "C:\Users\Asus\AppData\Local\Programs\Python\Python311\Lib\site-packages\django\shortcuts.py", line 24, in render
    content = loader.render_to_string(template_name, context, request, using=using)
              ^^^^^^^^^^^^^^^^^^^^^^^^^^^^^^^^^^^^^^^^^^^^^^^^^^^^^^^^^^^^^^^^^^^^^
  File "C:\Users\Asus\AppData\Local\Programs\Python\Python311\Lib\site-packages\django\template\loader.py", line 62, in render_to_string
    return template.render(context, request)
           ^^^^^^^^^^^^^^^^^^^^^^^^^^^^^^^^^
  File "C:\Users\Asus\AppData\Local\Programs\Python\Python311\Lib\site-packages\django\template\backends\django.py", line 63, in render
    reraise(exc, self.backend)
  File "C:\Users\Asus\AppData\Local\Programs\Python\Python311\Lib\site-packages\django\template\backends\django.py", line 84, in reraise
    raise new from exc
django.template.exceptions.TemplateDoesNotExist: base.html
ERROR 2023-09-18 14:26:43,933 basehttp 21476 23476 "GET /client/1 HTTP/1.1" 500 134836
INFO 2023-09-18 14:27:47,953 autoreload 5448 5992 Watching for file changes with StatReloader
ERROR 2023-09-18 14:27:51,445 log 5448 5616 Internal Server Error: /client/1
Traceback (most recent call last):
  File "C:\Users\Asus\AppData\Local\Programs\Python\Python311\Lib\site-packages\django\template\backends\django.py", line 61, in render
    return self.template.render(context)
           ^^^^^^^^^^^^^^^^^^^^^^^^^^^^^
  File "C:\Users\Asus\AppData\Local\Programs\Python\Python311\Lib\site-packages\django\template\base.py", line 175, in render
    return self._render(context)
           ^^^^^^^^^^^^^^^^^^^^^
  File "C:\Users\Asus\AppData\Local\Programs\Python\Python311\Lib\site-packages\django\template\base.py", line 167, in _render
    return self.nodelist.render(context)
           ^^^^^^^^^^^^^^^^^^^^^^^^^^^^^
  File "C:\Users\Asus\AppData\Local\Programs\Python\Python311\Lib\site-packages\django\template\base.py", line 1005, in render
    return SafeString("".join([node.render_annotated(context) for node in self]))
                              ^^^^^^^^^^^^^^^^^^^^^^^^^^^^^^^^^^^^^^^^^^^^^^^^^
  File "C:\Users\Asus\AppData\Local\Programs\Python\Python311\Lib\site-packages\django\template\base.py", line 1005, in <listcomp>
    return SafeString("".join([node.render_annotated(context) for node in self]))
                               ^^^^^^^^^^^^^^^^^^^^^^^^^^^^^^
  File "C:\Users\Asus\AppData\Local\Programs\Python\Python311\Lib\site-packages\django\template\base.py", line 966, in render_annotated
    return self.render(context)
           ^^^^^^^^^^^^^^^^^^^^
  File "C:\Users\Asus\AppData\Local\Programs\Python\Python311\Lib\site-packages\django\template\loader_tags.py", line 132, in render
    compiled_parent = self.get_parent(context)
                      ^^^^^^^^^^^^^^^^^^^^^^^^
  File "C:\Users\Asus\AppData\Local\Programs\Python\Python311\Lib\site-packages\django\template\loader_tags.py", line 129, in get_parent
    return self.find_template(parent, context)
           ^^^^^^^^^^^^^^^^^^^^^^^^^^^^^^^^^^^
  File "C:\Users\Asus\AppData\Local\Programs\Python\Python311\Lib\site-packages\django\template\loader_tags.py", line 107, in find_template
    template, origin = context.template.engine.find_template(
                       ^^^^^^^^^^^^^^^^^^^^^^^^^^^^^^^^^^^^^^
  File "C:\Users\Asus\AppData\Local\Programs\Python\Python311\Lib\site-packages\django\template\engine.py", line 161, in find_template
    raise TemplateDoesNotExist(name, tried=tried)
django.template.exceptions.TemplateDoesNotExist: templates.base.html

The above exception was the direct cause of the following exception:

Traceback (most recent call last):
  File "C:\Users\Asus\AppData\Local\Programs\Python\Python311\Lib\site-packages\django\core\handlers\exception.py", line 55, in inner
    response = get_response(request)
               ^^^^^^^^^^^^^^^^^^^^^
  File "C:\Users\Asus\AppData\Local\Programs\Python\Python311\Lib\site-packages\django\core\handlers\base.py", line 197, in _get_response
    response = wrapped_callback(request, *callback_args, **callback_kwargs)
               ^^^^^^^^^^^^^^^^^^^^^^^^^^^^^^^^^^^^^^^^^^^^^^^^^^^^^^^^^^^^
  File "D:\Django_HW\HW_2\views.py", line 15, in product_of_client
    return render(request, 'HW_2/products_of_client.html', {'client': client,
           ^^^^^^^^^^^^^^^^^^^^^^^^^^^^^^^^^^^^^^^^^^^^^^^^^^^^^^^^^^^^^^^^^^
  File "C:\Users\Asus\AppData\Local\Programs\Python\Python311\Lib\site-packages\django\shortcuts.py", line 24, in render
    content = loader.render_to_string(template_name, context, request, using=using)
              ^^^^^^^^^^^^^^^^^^^^^^^^^^^^^^^^^^^^^^^^^^^^^^^^^^^^^^^^^^^^^^^^^^^^^
  File "C:\Users\Asus\AppData\Local\Programs\Python\Python311\Lib\site-packages\django\template\loader.py", line 62, in render_to_string
    return template.render(context, request)
           ^^^^^^^^^^^^^^^^^^^^^^^^^^^^^^^^^
  File "C:\Users\Asus\AppData\Local\Programs\Python\Python311\Lib\site-packages\django\template\backends\django.py", line 63, in render
    reraise(exc, self.backend)
  File "C:\Users\Asus\AppData\Local\Programs\Python\Python311\Lib\site-packages\django\template\backends\django.py", line 84, in reraise
    raise new from exc
django.template.exceptions.TemplateDoesNotExist: templates.base.html
ERROR 2023-09-18 14:27:51,466 basehttp 5448 5616 "GET /client/1 HTTP/1.1" 500 135136
INFO 2023-09-18 14:40:39,152 autoreload 5448 5992 D:\Django_HW\HW_2\views.py changed, reloading.
INFO 2023-09-18 14:40:41,177 autoreload 664 16184 Watching for file changes with StatReloader
INFO 2023-09-18 14:41:35,822 autoreload 664 16184 D:\Django_HW\HW_2\views.py changed, reloading.
INFO 2023-09-18 14:41:36,826 autoreload 12740 8428 Watching for file changes with StatReloader
INFO 2023-09-18 14:41:42,552 autoreload 12740 8428 D:\Django_HW\HW_2\views.py changed, reloading.
INFO 2023-09-18 14:41:43,798 autoreload 11236 21584 Watching for file changes with StatReloader
INFO 2023-09-18 14:43:26,709 autoreload 11236 21584 D:\Django_HW\HW_2\views.py changed, reloading.
INFO 2023-09-18 14:43:27,980 autoreload 14964 17712 Watching for file changes with StatReloader
INFO 2023-09-18 14:44:04,054 autoreload 14964 17712 D:\Django_HW\HW_2\views.py changed, reloading.
INFO 2023-09-18 14:44:05,847 autoreload 21648 13868 Watching for file changes with StatReloader
INFO 2023-09-18 14:44:51,110 autoreload 21648 13868 D:\Django_HW\HW_2\views.py changed, reloading.
INFO 2023-09-18 14:44:52,196 autoreload 21900 24280 Watching for file changes with StatReloader
INFO 2023-09-18 14:47:17,265 autoreload 21900 24280 D:\Django_HW\HW_2\views.py changed, reloading.
INFO 2023-09-18 14:47:18,299 autoreload 24544 22864 Watching for file changes with StatReloader
INFO 2023-09-18 14:47:52,443 autoreload 24544 22864 D:\Django_HW\HW_2\views.py changed, reloading.
INFO 2023-09-18 14:47:53,612 autoreload 18476 9424 Watching for file changes with StatReloader
INFO 2023-09-18 14:48:42,279 autoreload 18476 9424 D:\Django_HW\HW_2\views.py changed, reloading.
INFO 2023-09-18 14:48:43,615 autoreload 21940 24132 Watching for file changes with StatReloader
INFO 2023-09-18 14:49:40,945 autoreload 21940 24132 D:\Django_HW\HW_2\views.py changed, reloading.
INFO 2023-09-18 14:49:42,279 autoreload 11496 17524 Watching for file changes with StatReloader
INFO 2023-09-18 14:49:47,285 autoreload 11496 17524 D:\Django_HW\HW_2\views.py changed, reloading.
INFO 2023-09-18 14:49:48,322 autoreload 21324 20548 Watching for file changes with StatReloader
INFO 2023-09-18 14:50:42,429 autoreload 21324 20548 D:\Django_HW\HW_2\views.py changed, reloading.
INFO 2023-09-18 14:50:43,542 autoreload 11840 17436 Watching for file changes with StatReloader
INFO 2023-09-18 14:56:55,059 autoreload 11840 17436 D:\Django_HW\HW_2\urls.py changed, reloading.
INFO 2023-09-18 14:56:56,519 autoreload 2404 7312 Watching for file changes with StatReloader
INFO 2023-09-18 14:57:56,192 autoreload 2404 7312 D:\Django_HW\HW_2\urls.py changed, reloading.
INFO 2023-09-18 14:57:57,312 autoreload 6264 24564 Watching for file changes with StatReloader
INFO 2023-09-18 14:58:28,057 autoreload 6264 24564 D:\Django_HW\HW_2\urls.py changed, reloading.
INFO 2023-09-18 14:58:29,145 autoreload 23016 15612 Watching for file changes with StatReloader
INFO 2023-09-18 14:59:29,633 autoreload 17412 17100 Watching for file changes with StatReloader
ERROR 2023-09-18 15:01:18,913 log 17412 11168 Internal Server Error: /products/1
Traceback (most recent call last):
  File "C:\Users\Asus\AppData\Local\Programs\Python\Python311\Lib\site-packages\django\template\backends\django.py", line 61, in render
    return self.template.render(context)
           ^^^^^^^^^^^^^^^^^^^^^^^^^^^^^
  File "C:\Users\Asus\AppData\Local\Programs\Python\Python311\Lib\site-packages\django\template\base.py", line 175, in render
    return self._render(context)
           ^^^^^^^^^^^^^^^^^^^^^
  File "C:\Users\Asus\AppData\Local\Programs\Python\Python311\Lib\site-packages\django\template\base.py", line 167, in _render
    return self.nodelist.render(context)
           ^^^^^^^^^^^^^^^^^^^^^^^^^^^^^
  File "C:\Users\Asus\AppData\Local\Programs\Python\Python311\Lib\site-packages\django\template\base.py", line 1005, in render
    return SafeString("".join([node.render_annotated(context) for node in self]))
                              ^^^^^^^^^^^^^^^^^^^^^^^^^^^^^^^^^^^^^^^^^^^^^^^^^
  File "C:\Users\Asus\AppData\Local\Programs\Python\Python311\Lib\site-packages\django\template\base.py", line 1005, in <listcomp>
    return SafeString("".join([node.render_annotated(context) for node in self]))
                               ^^^^^^^^^^^^^^^^^^^^^^^^^^^^^^
  File "C:\Users\Asus\AppData\Local\Programs\Python\Python311\Lib\site-packages\django\template\base.py", line 966, in render_annotated
    return self.render(context)
           ^^^^^^^^^^^^^^^^^^^^
  File "C:\Users\Asus\AppData\Local\Programs\Python\Python311\Lib\site-packages\django\template\loader_tags.py", line 132, in render
    compiled_parent = self.get_parent(context)
                      ^^^^^^^^^^^^^^^^^^^^^^^^
  File "C:\Users\Asus\AppData\Local\Programs\Python\Python311\Lib\site-packages\django\template\loader_tags.py", line 129, in get_parent
    return self.find_template(parent, context)
           ^^^^^^^^^^^^^^^^^^^^^^^^^^^^^^^^^^^
  File "C:\Users\Asus\AppData\Local\Programs\Python\Python311\Lib\site-packages\django\template\loader_tags.py", line 107, in find_template
    template, origin = context.template.engine.find_template(
                       ^^^^^^^^^^^^^^^^^^^^^^^^^^^^^^^^^^^^^^
  File "C:\Users\Asus\AppData\Local\Programs\Python\Python311\Lib\site-packages\django\template\engine.py", line 161, in find_template
    raise TemplateDoesNotExist(name, tried=tried)
django.template.exceptions.TemplateDoesNotExist: base.html

The above exception was the direct cause of the following exception:

Traceback (most recent call last):
  File "C:\Users\Asus\AppData\Local\Programs\Python\Python311\Lib\site-packages\django\core\handlers\exception.py", line 55, in inner
    response = get_response(request)
               ^^^^^^^^^^^^^^^^^^^^^
  File "C:\Users\Asus\AppData\Local\Programs\Python\Python311\Lib\site-packages\django\core\handlers\base.py", line 220, in _get_response
    response = response.render()
               ^^^^^^^^^^^^^^^^^
  File "C:\Users\Asus\AppData\Local\Programs\Python\Python311\Lib\site-packages\django\template\response.py", line 114, in render
    self.content = self.rendered_content
                   ^^^^^^^^^^^^^^^^^^^^^
  File "C:\Users\Asus\AppData\Local\Programs\Python\Python311\Lib\site-packages\django\template\response.py", line 92, in rendered_content
    return template.render(context, self._request)
           ^^^^^^^^^^^^^^^^^^^^^^^^^^^^^^^^^^^^^^^
  File "C:\Users\Asus\AppData\Local\Programs\Python\Python311\Lib\site-packages\django\template\backends\django.py", line 63, in render
    reraise(exc, self.backend)
  File "C:\Users\Asus\AppData\Local\Programs\Python\Python311\Lib\site-packages\django\template\backends\django.py", line 84, in reraise
    raise new from exc
django.template.exceptions.TemplateDoesNotExist: base.html
ERROR 2023-09-18 15:01:18,932 basehttp 17412 11168 "GET /products/1 HTTP/1.1" 500 128540
INFO 2023-09-18 15:04:33,945 autoreload 19864 16564 Watching for file changes with StatReloader
ERROR 2023-09-18 15:05:10,442 log 19864 13924 Internal Server Error: /products/1
Traceback (most recent call last):
  File "C:\Users\Asus\AppData\Local\Programs\Python\Python311\Lib\site-packages\django\template\backends\django.py", line 61, in render
    return self.template.render(context)
           ^^^^^^^^^^^^^^^^^^^^^^^^^^^^^
  File "C:\Users\Asus\AppData\Local\Programs\Python\Python311\Lib\site-packages\django\template\base.py", line 175, in render
    return self._render(context)
           ^^^^^^^^^^^^^^^^^^^^^
  File "C:\Users\Asus\AppData\Local\Programs\Python\Python311\Lib\site-packages\django\template\base.py", line 167, in _render
    return self.nodelist.render(context)
           ^^^^^^^^^^^^^^^^^^^^^^^^^^^^^
  File "C:\Users\Asus\AppData\Local\Programs\Python\Python311\Lib\site-packages\django\template\base.py", line 1005, in render
    return SafeString("".join([node.render_annotated(context) for node in self]))
                              ^^^^^^^^^^^^^^^^^^^^^^^^^^^^^^^^^^^^^^^^^^^^^^^^^
  File "C:\Users\Asus\AppData\Local\Programs\Python\Python311\Lib\site-packages\django\template\base.py", line 1005, in <listcomp>
    return SafeString("".join([node.render_annotated(context) for node in self]))
                               ^^^^^^^^^^^^^^^^^^^^^^^^^^^^^^
  File "C:\Users\Asus\AppData\Local\Programs\Python\Python311\Lib\site-packages\django\template\base.py", line 966, in render_annotated
    return self.render(context)
           ^^^^^^^^^^^^^^^^^^^^
  File "C:\Users\Asus\AppData\Local\Programs\Python\Python311\Lib\site-packages\django\template\loader_tags.py", line 132, in render
    compiled_parent = self.get_parent(context)
                      ^^^^^^^^^^^^^^^^^^^^^^^^
  File "C:\Users\Asus\AppData\Local\Programs\Python\Python311\Lib\site-packages\django\template\loader_tags.py", line 129, in get_parent
    return self.find_template(parent, context)
           ^^^^^^^^^^^^^^^^^^^^^^^^^^^^^^^^^^^
  File "C:\Users\Asus\AppData\Local\Programs\Python\Python311\Lib\site-packages\django\template\loader_tags.py", line 107, in find_template
    template, origin = context.template.engine.find_template(
                       ^^^^^^^^^^^^^^^^^^^^^^^^^^^^^^^^^^^^^^
  File "C:\Users\Asus\AppData\Local\Programs\Python\Python311\Lib\site-packages\django\template\engine.py", line 161, in find_template
    raise TemplateDoesNotExist(name, tried=tried)
django.template.exceptions.TemplateDoesNotExist: base.html

The above exception was the direct cause of the following exception:

Traceback (most recent call last):
  File "C:\Users\Asus\AppData\Local\Programs\Python\Python311\Lib\site-packages\django\core\handlers\exception.py", line 55, in inner
    response = get_response(request)
               ^^^^^^^^^^^^^^^^^^^^^
  File "C:\Users\Asus\AppData\Local\Programs\Python\Python311\Lib\site-packages\django\core\handlers\base.py", line 220, in _get_response
    response = response.render()
               ^^^^^^^^^^^^^^^^^
  File "C:\Users\Asus\AppData\Local\Programs\Python\Python311\Lib\site-packages\django\template\response.py", line 114, in render
    self.content = self.rendered_content
                   ^^^^^^^^^^^^^^^^^^^^^
  File "C:\Users\Asus\AppData\Local\Programs\Python\Python311\Lib\site-packages\django\template\response.py", line 92, in rendered_content
    return template.render(context, self._request)
           ^^^^^^^^^^^^^^^^^^^^^^^^^^^^^^^^^^^^^^^
  File "C:\Users\Asus\AppData\Local\Programs\Python\Python311\Lib\site-packages\django\template\backends\django.py", line 63, in render
    reraise(exc, self.backend)
  File "C:\Users\Asus\AppData\Local\Programs\Python\Python311\Lib\site-packages\django\template\backends\django.py", line 84, in reraise
    raise new from exc
django.template.exceptions.TemplateDoesNotExist: base.html
ERROR 2023-09-18 15:05:10,462 basehttp 19864 13924 "GET /products/1 HTTP/1.1" 500 128677
INFO 2023-09-18 15:05:44,855 basehttp 19864 13924 "GET /products/1 HTTP/1.1" 200 157
INFO 2023-09-18 15:05:47,997 basehttp 19864 13924 "GET /products/1 HTTP/1.1" 200 157
INFO 2023-09-18 15:06:03,990 basehttp 19864 13924 "GET /products/1 HTTP/1.1" 200 157
INFO 2023-09-18 15:06:07,154 basehttp 19864 13924 "GET /products/1 HTTP/1.1" 200 157
INFO 2023-09-18 15:12:31,297 basehttp 19864 9568 "GET /products/1 HTTP/1.1" 200 157
INFO 2023-09-18 15:13:06,151 basehttp 19864 9568 "GET /client/1 HTTP/1.1" 200 254
INFO 2023-09-18 15:21:50,675 autoreload 19716 10124 Watching for file changes with StatReloader
INFO 2023-09-18 15:21:52,131 basehttp 19716 17828 "GET /client/1 HTTP/1.1" 200 282
INFO 2023-09-18 15:26:17,353 autoreload 19716 10124 D:\Django_HW\HW_2\urls.py changed, reloading.
INFO 2023-09-18 15:26:18,494 autoreload 21760 8712 Watching for file changes with StatReloader
INFO 2023-09-18 15:27:11,672 autoreload 21760 8712 D:\Django_HW\HW_2\views.py changed, reloading.
INFO 2023-09-18 15:27:13,144 autoreload 21640 22636 Watching for file changes with StatReloader
INFO 2023-09-18 15:28:47,727 autoreload 21640 22636 D:\Django_HW\HW_2\views.py changed, reloading.
INFO 2023-09-18 15:28:48,869 autoreload 17076 18240 Watching for file changes with StatReloader
INFO 2023-09-18 15:29:47,407 autoreload 17076 18240 D:\Django_HW\HW_2\views.py changed, reloading.
INFO 2023-09-18 15:29:48,432 autoreload 22968 22680 Watching for file changes with StatReloader
INFO 2023-09-18 15:30:15,198 basehttp 22968 20864 "GET /client/1 HTTP/1.1" 200 282
INFO 2023-09-18 15:30:17,298 basehttp 22968 20864 "GET /client/1 HTTP/1.1" 200 282
WARNING 2023-09-18 15:30:38,160 log 22968 20864 Not Found: /orders/year/2023
WARNING 2023-09-18 15:30:38,161 basehttp 22968 20864 "GET /orders/year/2023 HTTP/1.1" 404 4223
INFO 2023-09-18 15:30:51,473 basehttp 22968 20864 "GET /orders/year/2023/1 HTTP/1.1" 301 0
ERROR 2023-09-18 15:30:51,581 log 22968 14136 Internal Server Error: /orders/year/2023/1/
Traceback (most recent call last):
  File "C:\Users\Asus\AppData\Local\Programs\Python\Python311\Lib\site-packages\django\core\handlers\exception.py", line 55, in inner
    response = get_response(request)
               ^^^^^^^^^^^^^^^^^^^^^
  File "C:\Users\Asus\AppData\Local\Programs\Python\Python311\Lib\site-packages\django\core\handlers\base.py", line 197, in _get_response
    response = wrapped_callback(request, *callback_args, **callback_kwargs)
               ^^^^^^^^^^^^^^^^^^^^^^^^^^^^^^^^^^^^^^^^^^^^^^^^^^^^^^^^^^^^
  File "C:\Users\Asus\AppData\Local\Programs\Python\Python311\Lib\site-packages\django\views\generic\base.py", line 104, in view
    return self.dispatch(request, *args, **kwargs)
           ^^^^^^^^^^^^^^^^^^^^^^^^^^^^^^^^^^^^^^^
  File "C:\Users\Asus\AppData\Local\Programs\Python\Python311\Lib\site-packages\django\views\generic\base.py", line 143, in dispatch
    return handler(request, *args, **kwargs)
           ^^^^^^^^^^^^^^^^^^^^^^^^^^^^^^^^^
  File "C:\Users\Asus\AppData\Local\Programs\Python\Python311\Lib\site-packages\django\views\generic\base.py", line 226, in get
    context = self.get_context_data(**kwargs)
              ^^^^^^^^^^^^^^^^^^^^^^^^^^^^^^^
  File "C:\Users\Asus\AppData\Local\Programs\Python\Python311\Lib\site-packages\django\views\generic\list.py", line 124, in get_context_data
    queryset = object_list if object_list is not None else self.object_list
                                                           ^^^^^^^^^^^^^^^^
AttributeError: 'AllYearProducts' object has no attribute 'object_list'
ERROR 2023-09-18 15:30:51,591 basehttp 22968 14136 "GET /orders/year/2023/1/ HTTP/1.1" 500 82509
INFO 2023-09-18 15:33:47,936 autoreload 22968 22680 D:\Django_HW\HW_2\views.py changed, reloading.
INFO 2023-09-18 15:33:48,900 autoreload 20728 19452 Watching for file changes with StatReloader
ERROR 2023-09-18 15:33:53,707 log 20728 24112 Internal Server Error: /orders/year/2023/1/
Traceback (most recent call last):
  File "C:\Users\Asus\AppData\Local\Programs\Python\Python311\Lib\site-packages\django\core\handlers\exception.py", line 55, in inner
    response = get_response(request)
               ^^^^^^^^^^^^^^^^^^^^^
  File "C:\Users\Asus\AppData\Local\Programs\Python\Python311\Lib\site-packages\django\core\handlers\base.py", line 197, in _get_response
    response = wrapped_callback(request, *callback_args, **callback_kwargs)
               ^^^^^^^^^^^^^^^^^^^^^^^^^^^^^^^^^^^^^^^^^^^^^^^^^^^^^^^^^^^^
  File "C:\Users\Asus\AppData\Local\Programs\Python\Python311\Lib\site-packages\django\views\generic\base.py", line 104, in view
    return self.dispatch(request, *args, **kwargs)
           ^^^^^^^^^^^^^^^^^^^^^^^^^^^^^^^^^^^^^^^
  File "C:\Users\Asus\AppData\Local\Programs\Python\Python311\Lib\site-packages\django\views\generic\base.py", line 143, in dispatch
    return handler(request, *args, **kwargs)
           ^^^^^^^^^^^^^^^^^^^^^^^^^^^^^^^^^
  File "C:\Users\Asus\AppData\Local\Programs\Python\Python311\Lib\site-packages\django\views\generic\base.py", line 226, in get
    context = self.get_context_data(**kwargs)
              ^^^^^^^^^^^^^^^^^^^^^^^^^^^^^^^
  File "C:\Users\Asus\AppData\Local\Programs\Python\Python311\Lib\site-packages\django\views\generic\list.py", line 124, in get_context_data
    queryset = object_list if object_list is not None else self.object_list
                                                           ^^^^^^^^^^^^^^^^
AttributeError: 'AllYearProducts' object has no attribute 'object_list'
ERROR 2023-09-18 15:33:53,716 basehttp 20728 24112 "GET /orders/year/2023/1/ HTTP/1.1" 500 82646
ERROR 2023-09-18 15:33:55,550 log 20728 24112 Internal Server Error: /orders/year/2023/1/
Traceback (most recent call last):
  File "C:\Users\Asus\AppData\Local\Programs\Python\Python311\Lib\site-packages\django\core\handlers\exception.py", line 55, in inner
    response = get_response(request)
               ^^^^^^^^^^^^^^^^^^^^^
  File "C:\Users\Asus\AppData\Local\Programs\Python\Python311\Lib\site-packages\django\core\handlers\base.py", line 197, in _get_response
    response = wrapped_callback(request, *callback_args, **callback_kwargs)
               ^^^^^^^^^^^^^^^^^^^^^^^^^^^^^^^^^^^^^^^^^^^^^^^^^^^^^^^^^^^^
  File "C:\Users\Asus\AppData\Local\Programs\Python\Python311\Lib\site-packages\django\views\generic\base.py", line 104, in view
    return self.dispatch(request, *args, **kwargs)
           ^^^^^^^^^^^^^^^^^^^^^^^^^^^^^^^^^^^^^^^
  File "C:\Users\Asus\AppData\Local\Programs\Python\Python311\Lib\site-packages\django\views\generic\base.py", line 143, in dispatch
    return handler(request, *args, **kwargs)
           ^^^^^^^^^^^^^^^^^^^^^^^^^^^^^^^^^
  File "C:\Users\Asus\AppData\Local\Programs\Python\Python311\Lib\site-packages\django\views\generic\base.py", line 226, in get
    context = self.get_context_data(**kwargs)
              ^^^^^^^^^^^^^^^^^^^^^^^^^^^^^^^
  File "C:\Users\Asus\AppData\Local\Programs\Python\Python311\Lib\site-packages\django\views\generic\list.py", line 124, in get_context_data
    queryset = object_list if object_list is not None else self.object_list
                                                           ^^^^^^^^^^^^^^^^
AttributeError: 'AllYearProducts' object has no attribute 'object_list'
ERROR 2023-09-18 15:33:55,558 basehttp 20728 24112 "GET /orders/year/2023/1/ HTTP/1.1" 500 82646
ERROR 2023-09-18 15:33:56,589 log 20728 24112 Internal Server Error: /orders/year/2023/1/
Traceback (most recent call last):
  File "C:\Users\Asus\AppData\Local\Programs\Python\Python311\Lib\site-packages\django\core\handlers\exception.py", line 55, in inner
    response = get_response(request)
               ^^^^^^^^^^^^^^^^^^^^^
  File "C:\Users\Asus\AppData\Local\Programs\Python\Python311\Lib\site-packages\django\core\handlers\base.py", line 197, in _get_response
    response = wrapped_callback(request, *callback_args, **callback_kwargs)
               ^^^^^^^^^^^^^^^^^^^^^^^^^^^^^^^^^^^^^^^^^^^^^^^^^^^^^^^^^^^^
  File "C:\Users\Asus\AppData\Local\Programs\Python\Python311\Lib\site-packages\django\views\generic\base.py", line 104, in view
    return self.dispatch(request, *args, **kwargs)
           ^^^^^^^^^^^^^^^^^^^^^^^^^^^^^^^^^^^^^^^
  File "C:\Users\Asus\AppData\Local\Programs\Python\Python311\Lib\site-packages\django\views\generic\base.py", line 143, in dispatch
    return handler(request, *args, **kwargs)
           ^^^^^^^^^^^^^^^^^^^^^^^^^^^^^^^^^
  File "C:\Users\Asus\AppData\Local\Programs\Python\Python311\Lib\site-packages\django\views\generic\base.py", line 226, in get
    context = self.get_context_data(**kwargs)
              ^^^^^^^^^^^^^^^^^^^^^^^^^^^^^^^
  File "C:\Users\Asus\AppData\Local\Programs\Python\Python311\Lib\site-packages\django\views\generic\list.py", line 124, in get_context_data
    queryset = object_list if object_list is not None else self.object_list
                                                           ^^^^^^^^^^^^^^^^
AttributeError: 'AllYearProducts' object has no attribute 'object_list'
ERROR 2023-09-18 15:33:56,600 basehttp 20728 24112 "GET /orders/year/2023/1/ HTTP/1.1" 500 82646
INFO 2023-09-18 15:37:37,529 autoreload 20728 19452 D:\Django_HW\HW_2\views.py changed, reloading.
INFO 2023-09-18 15:37:38,583 autoreload 22412 2580 Watching for file changes with StatReloader
ERROR 2023-09-18 15:37:42,496 log 22412 4844 Internal Server Error: /orders/year/2023/1/
Traceback (most recent call last):
  File "C:\Users\Asus\AppData\Local\Programs\Python\Python311\Lib\site-packages\django\core\handlers\exception.py", line 55, in inner
    response = get_response(request)
               ^^^^^^^^^^^^^^^^^^^^^
  File "C:\Users\Asus\AppData\Local\Programs\Python\Python311\Lib\site-packages\django\core\handlers\base.py", line 197, in _get_response
    response = wrapped_callback(request, *callback_args, **callback_kwargs)
               ^^^^^^^^^^^^^^^^^^^^^^^^^^^^^^^^^^^^^^^^^^^^^^^^^^^^^^^^^^^^
  File "C:\Users\Asus\AppData\Local\Programs\Python\Python311\Lib\site-packages\django\views\generic\base.py", line 104, in view
    return self.dispatch(request, *args, **kwargs)
           ^^^^^^^^^^^^^^^^^^^^^^^^^^^^^^^^^^^^^^^
  File "C:\Users\Asus\AppData\Local\Programs\Python\Python311\Lib\site-packages\django\views\generic\base.py", line 143, in dispatch
    return handler(request, *args, **kwargs)
           ^^^^^^^^^^^^^^^^^^^^^^^^^^^^^^^^^
  File "C:\Users\Asus\AppData\Local\Programs\Python\Python311\Lib\site-packages\django\views\generic\base.py", line 226, in get
    context = self.get_context_data(**kwargs)
              ^^^^^^^^^^^^^^^^^^^^^^^^^^^^^^^
  File "C:\Users\Asus\AppData\Local\Programs\Python\Python311\Lib\site-packages\django\views\generic\list.py", line 124, in get_context_data
    queryset = object_list if object_list is not None else self.object_list
                                                           ^^^^^^^^^^^^^^^^
AttributeError: 'AllYearProducts' object has no attribute 'object_list'
ERROR 2023-09-18 15:37:42,505 basehttp 22412 4844 "GET /orders/year/2023/1/ HTTP/1.1" 500 82646
INFO 2023-09-18 16:39:22,296 autoreload 22412 2580 D:\Django_HW\HW_2\views.py changed, reloading.
INFO 2023-09-18 16:39:23,693 autoreload 9744 18256 Watching for file changes with StatReloader
INFO 2023-09-18 16:47:15,284 autoreload 9744 18256 D:\Django_HW\HW_2\views.py changed, reloading.
INFO 2023-09-18 16:47:16,523 autoreload 19084 4156 Watching for file changes with StatReloader
INFO 2023-09-18 16:50:14,590 autoreload 19084 4156 D:\Django_HW\HW_2\views.py changed, reloading.
INFO 2023-09-18 16:50:15,917 autoreload 17820 22004 Watching for file changes with StatReloader
INFO 2023-09-18 16:50:21,857 autoreload 23576 7432 Watching for file changes with StatReloader
ERROR 2023-09-18 16:50:26,402 log 23576 19716 Internal Server Error: /orders/year/2023/1/
Traceback (most recent call last):
  File "C:\Users\Asus\AppData\Local\Programs\Python\Python311\Lib\site-packages\django\core\handlers\exception.py", line 55, in inner
    response = get_response(request)
               ^^^^^^^^^^^^^^^^^^^^^
  File "C:\Users\Asus\AppData\Local\Programs\Python\Python311\Lib\site-packages\django\core\handlers\base.py", line 197, in _get_response
    response = wrapped_callback(request, *callback_args, **callback_kwargs)
               ^^^^^^^^^^^^^^^^^^^^^^^^^^^^^^^^^^^^^^^^^^^^^^^^^^^^^^^^^^^^
  File "C:\Users\Asus\AppData\Local\Programs\Python\Python311\Lib\site-packages\django\views\generic\base.py", line 104, in view
    return self.dispatch(request, *args, **kwargs)
           ^^^^^^^^^^^^^^^^^^^^^^^^^^^^^^^^^^^^^^^
  File "C:\Users\Asus\AppData\Local\Programs\Python\Python311\Lib\site-packages\django\views\generic\base.py", line 143, in dispatch
    return handler(request, *args, **kwargs)
           ^^^^^^^^^^^^^^^^^^^^^^^^^^^^^^^^^
  File "C:\Users\Asus\AppData\Local\Programs\Python\Python311\Lib\site-packages\django\views\generic\base.py", line 226, in get
    context = self.get_context_data(**kwargs)
              ^^^^^^^^^^^^^^^^^^^^^^^^^^^^^^^
  File "C:\Users\Asus\AppData\Local\Programs\Python\Python311\Lib\site-packages\django\views\generic\list.py", line 124, in get_context_data
    queryset = object_list if object_list is not None else self.object_list
                                                           ^^^^^^^^^^^^^^^^
AttributeError: 'AllYearProducts' object has no attribute 'object_list'
ERROR 2023-09-18 16:50:26,411 basehttp 23576 19716 "GET /orders/year/2023/1/ HTTP/1.1" 500 82646
ERROR 2023-09-18 16:50:29,792 log 23576 19716 Internal Server Error: /orders/year/2023/1/
Traceback (most recent call last):
  File "C:\Users\Asus\AppData\Local\Programs\Python\Python311\Lib\site-packages\django\core\handlers\exception.py", line 55, in inner
    response = get_response(request)
               ^^^^^^^^^^^^^^^^^^^^^
  File "C:\Users\Asus\AppData\Local\Programs\Python\Python311\Lib\site-packages\django\core\handlers\base.py", line 197, in _get_response
    response = wrapped_callback(request, *callback_args, **callback_kwargs)
               ^^^^^^^^^^^^^^^^^^^^^^^^^^^^^^^^^^^^^^^^^^^^^^^^^^^^^^^^^^^^
  File "C:\Users\Asus\AppData\Local\Programs\Python\Python311\Lib\site-packages\django\views\generic\base.py", line 104, in view
    return self.dispatch(request, *args, **kwargs)
           ^^^^^^^^^^^^^^^^^^^^^^^^^^^^^^^^^^^^^^^
  File "C:\Users\Asus\AppData\Local\Programs\Python\Python311\Lib\site-packages\django\views\generic\base.py", line 143, in dispatch
    return handler(request, *args, **kwargs)
           ^^^^^^^^^^^^^^^^^^^^^^^^^^^^^^^^^
  File "C:\Users\Asus\AppData\Local\Programs\Python\Python311\Lib\site-packages\django\views\generic\base.py", line 226, in get
    context = self.get_context_data(**kwargs)
              ^^^^^^^^^^^^^^^^^^^^^^^^^^^^^^^
  File "C:\Users\Asus\AppData\Local\Programs\Python\Python311\Lib\site-packages\django\views\generic\list.py", line 124, in get_context_data
    queryset = object_list if object_list is not None else self.object_list
                                                           ^^^^^^^^^^^^^^^^
AttributeError: 'AllYearProducts' object has no attribute 'object_list'
ERROR 2023-09-18 16:50:29,801 basehttp 23576 19716 "GET /orders/year/2023/1/ HTTP/1.1" 500 82646
ERROR 2023-09-18 16:50:31,299 log 23576 19716 Internal Server Error: /orders/year/2023/1/
Traceback (most recent call last):
  File "C:\Users\Asus\AppData\Local\Programs\Python\Python311\Lib\site-packages\django\core\handlers\exception.py", line 55, in inner
    response = get_response(request)
               ^^^^^^^^^^^^^^^^^^^^^
  File "C:\Users\Asus\AppData\Local\Programs\Python\Python311\Lib\site-packages\django\core\handlers\base.py", line 197, in _get_response
    response = wrapped_callback(request, *callback_args, **callback_kwargs)
               ^^^^^^^^^^^^^^^^^^^^^^^^^^^^^^^^^^^^^^^^^^^^^^^^^^^^^^^^^^^^
  File "C:\Users\Asus\AppData\Local\Programs\Python\Python311\Lib\site-packages\django\views\generic\base.py", line 104, in view
    return self.dispatch(request, *args, **kwargs)
           ^^^^^^^^^^^^^^^^^^^^^^^^^^^^^^^^^^^^^^^
  File "C:\Users\Asus\AppData\Local\Programs\Python\Python311\Lib\site-packages\django\views\generic\base.py", line 143, in dispatch
    return handler(request, *args, **kwargs)
           ^^^^^^^^^^^^^^^^^^^^^^^^^^^^^^^^^
  File "C:\Users\Asus\AppData\Local\Programs\Python\Python311\Lib\site-packages\django\views\generic\base.py", line 226, in get
    context = self.get_context_data(**kwargs)
              ^^^^^^^^^^^^^^^^^^^^^^^^^^^^^^^
  File "C:\Users\Asus\AppData\Local\Programs\Python\Python311\Lib\site-packages\django\views\generic\list.py", line 124, in get_context_data
    queryset = object_list if object_list is not None else self.object_list
                                                           ^^^^^^^^^^^^^^^^
AttributeError: 'AllYearProducts' object has no attribute 'object_list'
ERROR 2023-09-18 16:50:31,307 basehttp 23576 19716 "GET /orders/year/2023/1/ HTTP/1.1" 500 82646
ERROR 2023-09-18 16:50:32,267 log 23576 19716 Internal Server Error: /orders/year/2023/1/
Traceback (most recent call last):
  File "C:\Users\Asus\AppData\Local\Programs\Python\Python311\Lib\site-packages\django\core\handlers\exception.py", line 55, in inner
    response = get_response(request)
               ^^^^^^^^^^^^^^^^^^^^^
  File "C:\Users\Asus\AppData\Local\Programs\Python\Python311\Lib\site-packages\django\core\handlers\base.py", line 197, in _get_response
    response = wrapped_callback(request, *callback_args, **callback_kwargs)
               ^^^^^^^^^^^^^^^^^^^^^^^^^^^^^^^^^^^^^^^^^^^^^^^^^^^^^^^^^^^^
  File "C:\Users\Asus\AppData\Local\Programs\Python\Python311\Lib\site-packages\django\views\generic\base.py", line 104, in view
    return self.dispatch(request, *args, **kwargs)
           ^^^^^^^^^^^^^^^^^^^^^^^^^^^^^^^^^^^^^^^
  File "C:\Users\Asus\AppData\Local\Programs\Python\Python311\Lib\site-packages\django\views\generic\base.py", line 143, in dispatch
    return handler(request, *args, **kwargs)
           ^^^^^^^^^^^^^^^^^^^^^^^^^^^^^^^^^
  File "C:\Users\Asus\AppData\Local\Programs\Python\Python311\Lib\site-packages\django\views\generic\base.py", line 226, in get
    context = self.get_context_data(**kwargs)
              ^^^^^^^^^^^^^^^^^^^^^^^^^^^^^^^
  File "C:\Users\Asus\AppData\Local\Programs\Python\Python311\Lib\site-packages\django\views\generic\list.py", line 124, in get_context_data
    queryset = object_list if object_list is not None else self.object_list
                                                           ^^^^^^^^^^^^^^^^
AttributeError: 'AllYearProducts' object has no attribute 'object_list'
ERROR 2023-09-18 16:50:32,275 basehttp 23576 19716 "GET /orders/year/2023/1/ HTTP/1.1" 500 82646
INFO 2023-09-18 16:52:00,297 basehttp 23576 19716 "GET /products/1 HTTP/1.1" 200 277
INFO 2023-09-18 16:52:17,746 basehttp 23576 19716 "GET /client/1 HTTP/1.1" 200 282
ERROR 2023-09-18 16:53:19,683 log 23576 19716 Internal Server Error: /orders/year/2023/1/
Traceback (most recent call last):
  File "C:\Users\Asus\AppData\Local\Programs\Python\Python311\Lib\site-packages\django\core\handlers\exception.py", line 55, in inner
    response = get_response(request)
               ^^^^^^^^^^^^^^^^^^^^^
  File "C:\Users\Asus\AppData\Local\Programs\Python\Python311\Lib\site-packages\django\core\handlers\base.py", line 197, in _get_response
    response = wrapped_callback(request, *callback_args, **callback_kwargs)
               ^^^^^^^^^^^^^^^^^^^^^^^^^^^^^^^^^^^^^^^^^^^^^^^^^^^^^^^^^^^^
  File "C:\Users\Asus\AppData\Local\Programs\Python\Python311\Lib\site-packages\django\views\generic\base.py", line 104, in view
    return self.dispatch(request, *args, **kwargs)
           ^^^^^^^^^^^^^^^^^^^^^^^^^^^^^^^^^^^^^^^
  File "C:\Users\Asus\AppData\Local\Programs\Python\Python311\Lib\site-packages\django\views\generic\base.py", line 143, in dispatch
    return handler(request, *args, **kwargs)
           ^^^^^^^^^^^^^^^^^^^^^^^^^^^^^^^^^
  File "C:\Users\Asus\AppData\Local\Programs\Python\Python311\Lib\site-packages\django\views\generic\base.py", line 226, in get
    context = self.get_context_data(**kwargs)
              ^^^^^^^^^^^^^^^^^^^^^^^^^^^^^^^
  File "C:\Users\Asus\AppData\Local\Programs\Python\Python311\Lib\site-packages\django\views\generic\list.py", line 124, in get_context_data
    queryset = object_list if object_list is not None else self.object_list
                                                           ^^^^^^^^^^^^^^^^
AttributeError: 'AllYearProducts' object has no attribute 'object_list'
ERROR 2023-09-18 16:53:19,691 basehttp 23576 19716 "GET /orders/year/2023/1/ HTTP/1.1" 500 82509
ERROR 2023-09-18 16:55:42,463 log 23576 19716 Internal Server Error: /orders/monthly/2023/01/1/
Traceback (most recent call last):
  File "C:\Users\Asus\AppData\Local\Programs\Python\Python311\Lib\site-packages\django\core\handlers\exception.py", line 55, in inner
    response = get_response(request)
               ^^^^^^^^^^^^^^^^^^^^^
  File "C:\Users\Asus\AppData\Local\Programs\Python\Python311\Lib\site-packages\django\core\handlers\base.py", line 197, in _get_response
    response = wrapped_callback(request, *callback_args, **callback_kwargs)
               ^^^^^^^^^^^^^^^^^^^^^^^^^^^^^^^^^^^^^^^^^^^^^^^^^^^^^^^^^^^^
  File "C:\Users\Asus\AppData\Local\Programs\Python\Python311\Lib\site-packages\django\views\generic\base.py", line 104, in view
    return self.dispatch(request, *args, **kwargs)
           ^^^^^^^^^^^^^^^^^^^^^^^^^^^^^^^^^^^^^^^
  File "C:\Users\Asus\AppData\Local\Programs\Python\Python311\Lib\site-packages\django\views\generic\base.py", line 143, in dispatch
    return handler(request, *args, **kwargs)
           ^^^^^^^^^^^^^^^^^^^^^^^^^^^^^^^^^
  File "C:\Users\Asus\AppData\Local\Programs\Python\Python311\Lib\site-packages\django\views\generic\base.py", line 226, in get
    context = self.get_context_data(**kwargs)
              ^^^^^^^^^^^^^^^^^^^^^^^^^^^^^^^
  File "C:\Users\Asus\AppData\Local\Programs\Python\Python311\Lib\site-packages\django\views\generic\list.py", line 124, in get_context_data
    queryset = object_list if object_list is not None else self.object_list
                                                           ^^^^^^^^^^^^^^^^
AttributeError: 'AllMonthProducts' object has no attribute 'object_list'
ERROR 2023-09-18 16:55:42,473 basehttp 23576 19716 "GET /orders/monthly/2023/01/1/ HTTP/1.1" 500 82702
INFO 2023-09-18 17:01:42,308 autoreload 23096 23924 Watching for file changes with StatReloader
INFO 2023-09-18 17:01:49,759 basehttp 23096 23516 "GET /client/1 HTTP/1.1" 200 282
INFO 2023-09-18 17:02:00,122 basehttp 23096 23516 "GET /client/10 HTTP/1.1" 200 285
WARNING 2023-09-18 17:02:10,860 log 23096 23516 Not Found: /client/15
WARNING 2023-09-18 17:02:10,865 basehttp 23096 23516 "GET /client/15 HTTP/1.1" 404 3493
INFO 2023-09-18 17:02:15,166 basehttp 23096 23516 "GET /client/14 HTTP/1.1" 200 282
INFO 2023-09-18 17:02:19,765 basehttp 23096 23516 "GET /client/11 HTTP/1.1" 200 285
INFO 2023-09-18 17:02:57,094 autoreload 23096 23924 D:\Django_HW\HW_2\views.py changed, reloading.
INFO 2023-09-18 17:02:58,214 autoreload 10956 23568 Watching for file changes with StatReloader
INFO 2023-09-18 17:04:00,665 autoreload 10956 23568 D:\Django_HW\HW_2\urls.py changed, reloading.
INFO 2023-09-18 17:04:01,815 autoreload 23848 18476 Watching for file changes with StatReloader
INFO 2023-09-18 17:18:17,706 autoreload 23848 18476 D:\Django_HW\HW_2\urls.py changed, reloading.
INFO 2023-09-18 17:18:18,845 autoreload 19676 23028 Watching for file changes with StatReloader
INFO 2023-09-21 12:54:05,833 autoreload 15980 18416 Watching for file changes with StatReloader
INFO 2023-09-21 12:54:13,319 basehttp 15980 7608 "GET / HTTP/1.1" 200 11
WARNING 2023-09-21 12:54:24,643 log 15980 7608 Not Found: /orders
WARNING 2023-09-21 12:54:24,644 basehttp 15980 7608 "GET /orders HTTP/1.1" 404 3498
INFO 2023-09-21 12:54:31,622 basehttp 15980 7608 "GET /product/add/ HTTP/1.1" 200 1492
ERROR 2023-09-21 12:55:09,205 log 15980 7608 Internal Server Error: /product/add/
Traceback (most recent call last):
  File "C:\Users\Asus\AppData\Local\Programs\Python\Python311\Lib\site-packages\django\db\backends\utils.py", line 89, in _execute
    return self.cursor.execute(sql, params)
           ^^^^^^^^^^^^^^^^^^^^^^^^^^^^^^^^
  File "C:\Users\Asus\AppData\Local\Programs\Python\Python311\Lib\site-packages\django\db\backends\sqlite3\base.py", line 328, in execute
    return super().execute(query, params)
           ^^^^^^^^^^^^^^^^^^^^^^^^^^^^^^
sqlite3.OperationalError: table HW_2_product has no column named image

The above exception was the direct cause of the following exception:

Traceback (most recent call last):
  File "C:\Users\Asus\AppData\Local\Programs\Python\Python311\Lib\site-packages\django\core\handlers\exception.py", line 55, in inner
    response = get_response(request)
               ^^^^^^^^^^^^^^^^^^^^^
  File "C:\Users\Asus\AppData\Local\Programs\Python\Python311\Lib\site-packages\django\core\handlers\base.py", line 197, in _get_response
    response = wrapped_callback(request, *callback_args, **callback_kwargs)
               ^^^^^^^^^^^^^^^^^^^^^^^^^^^^^^^^^^^^^^^^^^^^^^^^^^^^^^^^^^^^
  File "D:\Django_HW\HW_2\views.py", line 40, in catalog_form
    product.save()
  File "C:\Users\Asus\AppData\Local\Programs\Python\Python311\Lib\site-packages\django\db\models\base.py", line 814, in save
    self.save_base(
  File "C:\Users\Asus\AppData\Local\Programs\Python\Python311\Lib\site-packages\django\db\models\base.py", line 877, in save_base
    updated = self._save_table(
              ^^^^^^^^^^^^^^^^^
  File "C:\Users\Asus\AppData\Local\Programs\Python\Python311\Lib\site-packages\django\db\models\base.py", line 1020, in _save_table
    results = self._do_insert(
              ^^^^^^^^^^^^^^^^
  File "C:\Users\Asus\AppData\Local\Programs\Python\Python311\Lib\site-packages\django\db\models\base.py", line 1061, in _do_insert
    return manager._insert(
           ^^^^^^^^^^^^^^^^
  File "C:\Users\Asus\AppData\Local\Programs\Python\Python311\Lib\site-packages\django\db\models\manager.py", line 87, in manager_method
    return getattr(self.get_queryset(), name)(*args, **kwargs)
           ^^^^^^^^^^^^^^^^^^^^^^^^^^^^^^^^^^^^^^^^^^^^^^^^^^^
  File "C:\Users\Asus\AppData\Local\Programs\Python\Python311\Lib\site-packages\django\db\models\query.py", line 1805, in _insert
    return query.get_compiler(using=using).execute_sql(returning_fields)
           ^^^^^^^^^^^^^^^^^^^^^^^^^^^^^^^^^^^^^^^^^^^^^^^^^^^^^^^^^^^^^
  File "C:\Users\Asus\AppData\Local\Programs\Python\Python311\Lib\site-packages\django\db\models\sql\compiler.py", line 1822, in execute_sql
    cursor.execute(sql, params)
  File "C:\Users\Asus\AppData\Local\Programs\Python\Python311\Lib\site-packages\django\db\backends\utils.py", line 102, in execute
    return super().execute(sql, params)
           ^^^^^^^^^^^^^^^^^^^^^^^^^^^^
  File "C:\Users\Asus\AppData\Local\Programs\Python\Python311\Lib\site-packages\django\db\backends\utils.py", line 67, in execute
    return self._execute_with_wrappers(
           ^^^^^^^^^^^^^^^^^^^^^^^^^^^^
  File "C:\Users\Asus\AppData\Local\Programs\Python\Python311\Lib\site-packages\django\db\backends\utils.py", line 80, in _execute_with_wrappers
    return executor(sql, params, many, context)
           ^^^^^^^^^^^^^^^^^^^^^^^^^^^^^^^^^^^^
  File "C:\Users\Asus\AppData\Local\Programs\Python\Python311\Lib\site-packages\django\db\backends\utils.py", line 84, in _execute
    with self.db.wrap_database_errors:
  File "C:\Users\Asus\AppData\Local\Programs\Python\Python311\Lib\site-packages\django\db\utils.py", line 91, in __exit__
    raise dj_exc_value.with_traceback(traceback) from exc_value
  File "C:\Users\Asus\AppData\Local\Programs\Python\Python311\Lib\site-packages\django\db\backends\utils.py", line 89, in _execute
    return self.cursor.execute(sql, params)
           ^^^^^^^^^^^^^^^^^^^^^^^^^^^^^^^^
  File "C:\Users\Asus\AppData\Local\Programs\Python\Python311\Lib\site-packages\django\db\backends\sqlite3\base.py", line 328, in execute
    return super().execute(query, params)
           ^^^^^^^^^^^^^^^^^^^^^^^^^^^^^^
django.db.utils.OperationalError: table HW_2_product has no column named image
ERROR 2023-09-21 12:55:09,230 basehttp 15980 7608 "POST /product/add/ HTTP/1.1" 500 155212
INFO 2023-09-21 13:47:28,754 autoreload 20532 21720 Watching for file changes with StatReloader
INFO 2023-09-21 13:47:36,725 basehttp 20532 17848 "GET /product/add/ HTTP/1.1" 200 1492
INFO 2023-09-21 13:47:53,660 basehttp 20532 17848 "POST /product/add/ HTTP/1.1" 200 1560
INFO 2023-09-21 13:50:20,641 autoreload 20532 21720 D:\Django_HW\HW_2\urls.py changed, reloading.
INFO 2023-09-21 13:50:21,755 autoreload 11996 24968 Watching for file changes with StatReloader
INFO 2023-09-21 13:50:31,381 basehttp 11996 21804 "GET /add_product HTTP/1.1" 301 0
INFO 2023-09-21 13:50:31,412 basehttp 11996 25584 "GET /add_product/ HTTP/1.1" 200 1492
INFO 2023-09-21 13:53:12,931 basehttp 11996 25584 "GET /add_product/ HTTP/1.1" 200 1492
INFO 2023-09-21 13:53:26,569 basehttp 11996 25584 "POST /add_product/ HTTP/1.1" 200 1562
INFO 2023-09-25 10:47:15,927 autoreload 24792 7448 Watching for file changes with StatReloader
INFO 2023-09-25 10:47:34,446 basehttp 24792 10448 "GET / HTTP/1.1" 200 11
INFO 2023-09-25 10:47:41,466 basehttp 24792 10448 "GET /admin HTTP/1.1" 301 0
INFO 2023-09-25 10:47:41,483 basehttp 24792 21044 "GET /admin/ HTTP/1.1" 302 0
INFO 2023-09-25 10:47:41,652 basehttp 24792 21044 "GET /admin/login/?next=/admin/ HTTP/1.1" 200 4181
INFO 2023-09-25 10:47:42,070 basehttp 24792 21044 "GET /static/admin/css/base.css HTTP/1.1" 200 21207
INFO 2023-09-25 10:47:42,071 basehttp 24792 17648 "GET /static/admin/css/nav_sidebar.css HTTP/1.1" 200 2694
INFO 2023-09-25 10:47:42,107 basehttp 24792 2632 "GET /static/admin/css/login.css HTTP/1.1" 200 958
INFO 2023-09-25 10:47:42,107 basehttp 24792 21292 "GET /static/admin/css/responsive.css HTTP/1.1" 200 18533
INFO 2023-09-25 10:47:42,117 basehttp 24792 21044 "GET /static/admin/js/nav_sidebar.js HTTP/1.1" 200 3063
INFO 2023-09-25 10:47:42,118 basehttp 24792 5788 "GET /static/admin/css/dark_mode.css HTTP/1.1" 200 2929
INFO 2023-09-25 10:47:42,128 basehttp 24792 23496 "GET /static/admin/js/theme.js HTTP/1.1" 200 1943
INFO 2023-09-25 10:49:22,786 autoreload 24792 7448 D:\Django_HW\seminars_proj\settings.py changed, reloading.
INFO 2023-09-25 10:49:24,043 autoreload 10208 11904 Watching for file changes with StatReloader
INFO 2023-09-25 10:49:37,731 autoreload 24196 5448 Watching for file changes with StatReloader
INFO 2023-09-25 10:49:44,944 basehttp 24196 19040 "GET /admin/ HTTP/1.1" 302 0
INFO 2023-09-25 10:49:45,018 basehttp 24196 19040 "GET /admin/login/?next=/admin/ HTTP/1.1" 200 4267
INFO 2023-09-25 10:53:04,161 autoreload 10152 24544 Watching for file changes with StatReloader
INFO 2023-09-25 10:53:36,568 basehttp 10152 20496 "POST /admin/login/?next=/admin/ HTTP/1.1" 302 0
INFO 2023-09-25 10:53:36,661 basehttp 10152 20496 "GET /admin/ HTTP/1.1" 200 5858
INFO 2023-09-25 10:53:36,800 basehttp 10152 20496 "GET /static/admin/css/dashboard.css HTTP/1.1" 200 441
INFO 2023-09-25 10:53:36,837 basehttp 10152 22988 "GET /static/admin/img/icon-changelink.svg HTTP/1.1" 200 380
INFO 2023-09-25 10:53:36,840 basehttp 10152 20496 "GET /static/admin/img/icon-addlink.svg HTTP/1.1" 200 331
INFO 2023-09-25 11:00:05,132 autoreload 10152 24544 D:\Django_HW\HW_2\models.py changed, reloading.
INFO 2023-09-25 11:00:06,359 autoreload 21356 2532 Watching for file changes with StatReloader
INFO 2023-09-25 11:00:53,007 autoreload 21356 2532 D:\Django_HW\HW_2\models.py changed, reloading.
INFO 2023-09-25 11:00:54,482 autoreload 18876 21360 Watching for file changes with StatReloader
INFO 2023-09-25 11:34:13,247 autoreload 11732 19368 Watching for file changes with StatReloader
INFO 2023-09-25 11:34:18,921 basehttp 11732 25272 "GET /admin/ HTTP/1.1" 200 6968
INFO 2023-09-25 11:35:08,524 autoreload 11732 19368 D:\Django_HW\HW_2\admin.py changed, reloading.
INFO 2023-09-25 11:35:09,717 autoreload 8336 20372 Watching for file changes with StatReloader
INFO 2023-09-25 11:35:59,846 autoreload 22044 22960 Watching for file changes with StatReloader
INFO 2023-09-25 11:36:02,997 basehttp 22044 23220 "GET /admin/ HTTP/1.1" 200 8279
INFO 2023-09-25 11:38:17,451 autoreload 22044 22960 D:\Django_HW\HW_2\models.py changed, reloading.
INFO 2023-09-25 11:38:18,505 autoreload 6756 17636 Watching for file changes with StatReloader
INFO 2023-09-25 11:39:30,586 autoreload 6756 17636 D:\Django_HW\HW_2\models.py changed, reloading.
INFO 2023-09-25 11:39:31,805 autoreload 17268 13604 Watching for file changes with StatReloader
INFO 2023-09-25 11:41:50,562 autoreload 9800 7872 Watching for file changes with StatReloader
INFO 2023-09-25 11:41:55,801 basehttp 9800 19964 "GET /admin/ HTTP/1.1" 200 8279
INFO 2023-09-25 11:42:03,721 basehttp 9800 19964 "GET /admin/HW_2/goods/add/ HTTP/1.1" 200 14128
INFO 2023-09-25 11:42:03,777 basehttp 9800 24848 "GET /admin/jsi18n/ HTTP/1.1" 200 16066
INFO 2023-09-25 11:42:04,109 basehttp 9800 17632 "GET /static/admin/js/jquery.init.js HTTP/1.1" 200 347
INFO 2023-09-25 11:42:04,146 basehttp 9800 17632 "GET /static/admin/js/urlify.js HTTP/1.1" 200 7887
INFO 2023-09-25 11:42:04,169 basehttp 9800 19964 "GET /static/admin/css/forms.css HTTP/1.1" 200 9047
INFO 2023-09-25 11:42:04,216 basehttp 9800 17372 "GET /static/admin/js/core.js HTTP/1.1" 200 5682
INFO 2023-09-25 11:42:04,233 basehttp 9800 17632 "GET /static/admin/js/prepopulate.js HTTP/1.1" 200 1531
INFO 2023-09-25 11:42:04,237 basehttp 9800 15228 "GET /static/admin/js/admin/RelatedObjectLookups.js HTTP/1.1" 200 8943
INFO 2023-09-25 11:42:04,237 basehttp 9800 24848 "GET /static/admin/js/actions.js HTTP/1.1" 200 7872
INFO 2023-09-25 11:42:04,256 basehttp 9800 17372 "GET /static/admin/css/widgets.css HTTP/1.1" 200 11900
INFO 2023-09-25 11:42:04,303 basehttp 9800 22436 "GET /static/admin/js/vendor/jquery/jquery.js HTTP/1.1" 200 292458
INFO 2023-09-25 11:42:04,340 basehttp 9800 22436 "GET /static/admin/js/prepopulate_init.js HTTP/1.1" 200 586
INFO 2023-09-25 11:42:04,342 basehttp 9800 19964 "GET /static/admin/js/vendor/xregexp/xregexp.js HTTP/1.1" 200 232381
INFO 2023-09-25 11:42:04,367 basehttp 9800 19964 "GET /static/admin/img/icon-viewlink.svg HTTP/1.1" 200 581
INFO 2023-09-25 11:42:04,373 basehttp 9800 22436 "GET /static/admin/js/change_form.js HTTP/1.1" 200 606
INFO 2023-09-25 11:42:06,764 basehttp 9800 22436 "GET /admin/ HTTP/1.1" 200 8279
INFO 2023-09-25 11:47:52,458 autoreload 9800 7872 D:\Django_HW\HW_2\admin.py changed, reloading.
INFO 2023-09-25 11:47:53,561 autoreload 25108 18788 Watching for file changes with StatReloader
INFO 2023-09-25 11:48:34,998 autoreload 25108 18788 D:\Django_HW\HW_2\admin.py changed, reloading.
INFO 2023-09-25 11:48:36,280 autoreload 23180 18940 Watching for file changes with StatReloader
INFO 2023-09-25 11:49:05,632 autoreload 23180 18940 D:\Django_HW\HW_2\models.py changed, reloading.
INFO 2023-09-25 11:49:06,760 autoreload 22888 2964 Watching for file changes with StatReloader
INFO 2023-09-25 11:50:10,454 autoreload 22888 2964 D:\Django_HW\HW_2\admin.py changed, reloading.
INFO 2023-09-25 11:50:11,504 autoreload 8128 5260 Watching for file changes with StatReloader
INFO 2023-09-25 11:50:46,532 basehttp 8128 18636 "GET /admin/ HTTP/1.1" 200 8279
INFO 2023-09-25 11:50:55,114 basehttp 8128 18636 "GET /admin/HW_2/product/add/ HTTP/1.1" 200 12440
INFO 2023-09-25 11:50:55,150 basehttp 8128 18636 "GET /admin/jsi18n/ HTTP/1.1" 200 16066
INFO 2023-09-25 11:51:01,284 basehttp 8128 18636 "GET /admin/ HTTP/1.1" 200 8279
INFO 2023-09-25 11:51:53,062 autoreload 8128 5260 D:\Django_HW\HW_2\admin.py changed, reloading.
INFO 2023-09-25 11:51:54,138 autoreload 22956 16828 Watching for file changes with StatReloader
INFO 2023-09-25 11:52:02,284 autoreload 22956 16828 D:\Django_HW\HW_2\admin.py changed, reloading.
INFO 2023-09-25 11:52:03,425 autoreload 444 11004 Watching for file changes with StatReloader
INFO 2023-09-25 11:52:55,448 autoreload 444 11004 D:\Django_HW\HW_2\admin.py changed, reloading.
INFO 2023-09-25 11:52:56,732 autoreload 20272 18568 Watching for file changes with StatReloader
INFO 2023-09-25 11:53:12,935 autoreload 20272 18568 D:\Django_HW\HW_2\admin.py changed, reloading.
INFO 2023-09-25 11:53:14,041 autoreload 6732 25396 Watching for file changes with StatReloader
INFO 2023-09-25 11:53:31,830 basehttp 6732 18496 "GET /admin/ HTTP/1.1" 200 8279
INFO 2023-09-25 11:56:15,462 autoreload 6732 25396 D:\Django_HW\HW_2\admin.py changed, reloading.
INFO 2023-09-25 11:56:16,553 autoreload 12056 10380 Watching for file changes with StatReloader
INFO 2023-09-25 11:56:37,081 autoreload 12056 10380 D:\Django_HW\HW_2\admin.py changed, reloading.
INFO 2023-09-25 11:56:38,078 autoreload 5776 23732 Watching for file changes with StatReloader
INFO 2023-09-25 11:56:47,782 autoreload 5776 23732 D:\Django_HW\HW_2\admin.py changed, reloading.
INFO 2023-09-25 11:56:48,820 autoreload 22428 15976 Watching for file changes with StatReloader
INFO 2023-09-25 11:58:22,157 autoreload 22428 15976 D:\Django_HW\HW_2\admin.py changed, reloading.
INFO 2023-09-25 11:58:23,228 autoreload 23496 9424 Watching for file changes with StatReloader
INFO 2023-09-25 12:01:54,532 autoreload 23496 9424 D:\Django_HW\HW_2\admin.py changed, reloading.
INFO 2023-09-25 12:01:55,635 autoreload 16064 25444 Watching for file changes with StatReloader
INFO 2023-09-25 12:02:24,648 autoreload 16064 25444 D:\Django_HW\HW_2\admin.py changed, reloading.
INFO 2023-09-25 12:02:25,925 autoreload 17792 17564 Watching for file changes with StatReloader
INFO 2023-09-25 12:12:56,664 autoreload 17792 17564 D:\Django_HW\HW_2\admin.py changed, reloading.
INFO 2023-09-25 12:12:58,477 autoreload 6492 20036 Watching for file changes with StatReloader
INFO 2023-09-25 12:16:48,104 autoreload 6492 20036 D:\Django_HW\HW_2\admin.py changed, reloading.
INFO 2023-09-25 12:16:49,427 autoreload 15564 17860 Watching for file changes with StatReloader
INFO 2023-09-25 12:18:38,315 autoreload 15564 17860 D:\Django_HW\HW_2\admin.py changed, reloading.
INFO 2023-09-25 12:18:39,658 autoreload 444 16892 Watching for file changes with StatReloader
INFO 2023-09-25 12:19:22,773 autoreload 444 16892 D:\Django_HW\HW_2\admin.py changed, reloading.
INFO 2023-09-25 12:19:23,886 autoreload 18004 23872 Watching for file changes with StatReloader
INFO 2023-09-25 12:22:07,952 autoreload 18816 24008 Watching for file changes with StatReloader
INFO 2023-09-25 12:25:52,923 autoreload 18816 24008 D:\Django_HW\HW_2\admin.py changed, reloading.
INFO 2023-09-25 12:25:54,229 autoreload 15088 22240 Watching for file changes with StatReloader
INFO 2023-09-25 12:27:47,486 autoreload 15088 22240 D:\Django_HW\HW_2\admin.py changed, reloading.
INFO 2023-09-25 12:27:49,037 autoreload 10380 1888 Watching for file changes with StatReloader
INFO 2023-09-25 12:30:35,897 autoreload 10380 1888 D:\Django_HW\HW_2\admin.py changed, reloading.
INFO 2023-09-25 12:30:37,346 autoreload 24680 19816 Watching for file changes with StatReloader
INFO 2023-09-25 12:31:29,259 autoreload 24680 19816 D:\Django_HW\HW_2\admin.py changed, reloading.
INFO 2023-09-25 12:31:30,387 autoreload 4996 23440 Watching for file changes with StatReloader
INFO 2023-09-25 12:32:36,566 autoreload 4996 23440 D:\Django_HW\HW_2\admin.py changed, reloading.
INFO 2023-09-25 12:32:37,724 autoreload 19852 14220 Watching for file changes with StatReloader
INFO 2023-09-25 12:33:10,646 autoreload 19852 14220 D:\Django_HW\HW_2\admin.py changed, reloading.
INFO 2023-09-25 12:33:11,697 autoreload 16728 17860 Watching for file changes with StatReloader
INFO 2023-09-25 12:33:44,358 basehttp 16728 14424 "GET /admin/ HTTP/1.1" 200 8279
INFO 2023-09-25 12:33:50,855 basehttp 16728 14424 "GET /admin/HW_2/client/add/ HTTP/1.1" 200 11754
INFO 2023-09-25 12:33:50,919 basehttp 16728 14424 "GET /admin/jsi18n/ HTTP/1.1" 200 16066
INFO 2023-09-25 12:34:03,498 basehttp 16728 14424 "GET /admin/auth/user/add/ HTTP/1.1" 200 12724
INFO 2023-09-25 12:34:03,522 basehttp 16728 14424 "GET /admin/jsi18n/ HTTP/1.1" 200 16066
INFO 2023-09-25 12:34:06,986 basehttp 16728 14424 "GET /admin/auth/group/add/ HTTP/1.1" 200 14974
INFO 2023-09-25 12:34:07,010 basehttp 16728 14424 "GET /admin/jsi18n/ HTTP/1.1" 200 16066
INFO 2023-09-25 12:34:07,200 basehttp 16728 2636 "GET /static/admin/js/SelectBox.js HTTP/1.1" 200 4530
INFO 2023-09-25 12:34:07,224 basehttp 16728 25380 "GET /static/admin/js/SelectFilter2.js HTTP/1.1" 200 15292
INFO 2023-09-25 12:34:07,299 basehttp 16728 2636 "GET /static/admin/img/search.svg HTTP/1.1" 200 458
INFO 2023-09-25 12:34:07,300 basehttp 16728 14424 "GET /static/admin/img/selector-icons.svg HTTP/1.1" 200 3291
INFO 2023-09-25 12:34:07,303 basehttp 16728 25380 "GET /static/admin/img/icon-unknown.svg HTTP/1.1" 200 655
INFO 2023-09-25 12:34:07,315 basehttp 16728 10348 "GET /static/admin/img/icon-unknown-alt.svg HTTP/1.1" 200 655
INFO 2023-09-25 12:34:11,466 basehttp 16728 10348 "GET /admin/HW_2/product/add/ HTTP/1.1" 200 11110
INFO 2023-09-25 12:34:11,494 basehttp 16728 10348 "GET /admin/jsi18n/ HTTP/1.1" 200 16066
INFO 2023-09-28 12:26:52,585 autoreload 2156 24156 Watching for file changes with StatReloader
INFO 2023-09-28 12:27:00,681 basehttp 2156 16300 "GET /admin/HW_2/product/add/ HTTP/1.1" 200 20930
INFO 2023-09-28 12:27:00,726 basehttp 2156 16300 "GET /static/admin/css/base.css HTTP/1.1" 304 0
INFO 2023-09-28 12:27:00,734 basehttp 2156 16300 "GET /static/admin/css/dark_mode.css HTTP/1.1" 304 0
INFO 2023-09-28 12:27:00,734 basehttp 2156 18976 "GET /static/admin/css/nav_sidebar.css HTTP/1.1" 304 0
INFO 2023-09-28 12:27:00,747 basehttp 2156 18976 "GET /static/admin/js/vendor/jquery/jquery.js HTTP/1.1" 304 0
INFO 2023-09-28 12:27:00,752 basehttp 2156 16300 "GET /static/admin/js/jquery.init.js HTTP/1.1" 304 0
INFO 2023-09-28 12:27:00,753 basehttp 2156 18976 "GET /static/admin/js/core.js HTTP/1.1" 304 0
INFO 2023-09-28 12:27:00,757 basehttp 2156 16300 "GET /static/admin/js/urlify.js HTTP/1.1" 304 0
INFO 2023-09-28 12:27:00,770 basehttp 2156 16300 "GET /static/admin/css/responsive.css HTTP/1.1" 304 0
INFO 2023-09-28 12:27:00,771 basehttp 2156 18976 "GET /static/admin/js/prepopulate.js HTTP/1.1" 304 0
INFO 2023-09-28 12:27:00,779 basehttp 2156 18976 "GET /static/admin/js/vendor/xregexp/xregexp.js HTTP/1.1" 304 0
INFO 2023-09-28 12:27:00,783 basehttp 2156 18976 "GET /static/admin/js/prepopulate_init.js HTTP/1.1" 304 0
INFO 2023-09-28 12:27:00,812 basehttp 2156 7796 "GET /static/admin/js/admin/RelatedObjectLookups.js HTTP/1.1" 304 0
INFO 2023-09-28 12:27:00,817 basehttp 2156 16300 "GET /static/debug_toolbar/css/toolbar.css HTTP/1.1" 200 12621
INFO 2023-09-28 12:27:00,841 basehttp 2156 22860 "GET /static/admin/js/actions.js HTTP/1.1" 304 0
INFO 2023-09-28 12:27:00,846 basehttp 2156 18976 "GET /static/debug_toolbar/js/toolbar.js HTTP/1.1" 200 13404
INFO 2023-09-28 12:27:00,844 basehttp 2156 19184 "GET /static/admin/css/forms.css HTTP/1.1" 200 9047
INFO 2023-09-28 12:27:00,867 basehttp 2156 18976 "GET /static/admin/css/widgets.css HTTP/1.1" 304 0
INFO 2023-09-28 12:27:00,883 basehttp 2156 18976 "GET /static/admin/js/theme.js HTTP/1.1" 304 0
INFO 2023-09-28 12:27:00,891 basehttp 2156 18976 "GET /static/admin/js/nav_sidebar.js HTTP/1.1" 304 0
INFO 2023-09-28 12:27:00,903 basehttp 2156 14884 "GET /admin/jsi18n/ HTTP/1.1" 200 16066
INFO 2023-09-28 12:27:00,919 basehttp 2156 18976 "GET /static/admin/js/change_form.js HTTP/1.1" 200 606
INFO 2023-09-28 12:27:00,989 basehttp 2156 14884 "GET /static/admin/img/icon-addlink.svg HTTP/1.1" 304 0
INFO 2023-09-28 12:27:00,996 basehttp 2156 18976 "GET /static/debug_toolbar/css/print.css HTTP/1.1" 200 43
INFO 2023-09-28 12:27:01,058 basehttp 2156 18976 "GET /static/debug_toolbar/js/utils.js HTTP/1.1" 200 4527
INFO 2023-09-28 12:33:12,174 autoreload 2156 24156 D:\Django_HW\seminars_proj\settings.py changed, reloading.
INFO 2023-09-28 12:33:13,381 autoreload 3904 9780 Watching for file changes with StatReloader
INFO 2023-09-28 12:33:25,816 autoreload 3904 9780 D:\Django_HW\seminars_proj\settings.py changed, reloading.
INFO 2023-09-28 12:33:27,219 autoreload 16980 18512 Watching for file changes with StatReloader
INFO 2023-09-28 12:33:55,750 autoreload 16980 18512 D:\Django_HW\seminars_proj\settings.py changed, reloading.
INFO 2023-09-28 12:33:57,019 autoreload 11068 20800 Watching for file changes with StatReloader
INFO 2023-09-28 12:34:06,456 autoreload 11068 20800 D:\Django_HW\seminars_proj\settings.py changed, reloading.
INFO 2023-09-28 12:34:07,836 autoreload 14424 16568 Watching for file changes with StatReloader
INFO 2023-09-28 12:34:39,539 autoreload 14424 16568 D:\Django_HW\seminars_proj\settings.py changed, reloading.
INFO 2023-09-28 12:34:40,849 autoreload 22204 24184 Watching for file changes with StatReloader
INFO 2023-09-28 12:34:58,754 autoreload 22204 24184 D:\Django_HW\seminars_proj\settings.py changed, reloading.
INFO 2023-09-28 12:35:00,178 autoreload 21964 8128 Watching for file changes with StatReloader
INFO 2023-09-28 12:36:37,900 autoreload 21964 8128 D:\Django_HW\seminars_proj\settings.py changed, reloading.
INFO 2023-09-28 12:36:39,231 autoreload 18188 22168 Watching for file changes with StatReloader
INFO 2023-09-28 12:36:47,641 autoreload 18188 22168 D:\Django_HW\seminars_proj\settings.py changed, reloading.
INFO 2023-09-28 12:36:49,236 autoreload 6452 22588 Watching for file changes with StatReloader
INFO 2023-09-28 12:42:31,016 autoreload 6452 22588 D:\Django_HW\seminars_proj\settings.py changed, reloading.
INFO 2023-09-28 12:42:32,314 autoreload 24660 22544 Watching for file changes with StatReloader
INFO 2023-09-28 12:45:04,813 autoreload 24660 22544 D:\Django_HW\seminars_proj\settings.py changed, reloading.
INFO 2023-09-28 12:45:06,390 autoreload 23072 19868 Watching for file changes with StatReloader
INFO 2023-09-28 12:46:02,631 autoreload 23072 19868 D:\Django_HW\seminars_proj\settings.py changed, reloading.
INFO 2023-09-28 12:46:03,945 autoreload 18488 24996 Watching for file changes with StatReloader
INFO 2023-09-28 12:48:24,865 autoreload 18488 24996 D:\Django_HW\seminars_proj\settings.py changed, reloading.
INFO 2023-09-28 12:48:26,178 autoreload 24264 3696 Watching for file changes with StatReloader
